
2021-07-22 01:41:04_000725_현대건설우
Traceback (most recent call last):
  File "C:\Users\kai\PycharmProjects\pythonProject\noname\noname\spiders\report_spider.py", line 144, in document_scraping
    button = self.driver.find_element_by_xpath(
  File "c:\users\kai\pycharmprojects\pythonproject\venv\lib\site-packages\selenium\webdriver\remote\webdriver.py", line 394, in find_element_by_xpath
    return self.find_element(by=By.XPATH, value=xpath)
  File "c:\users\kai\pycharmprojects\pythonproject\venv\lib\site-packages\selenium\webdriver\remote\webdriver.py", line 976, in find_element
    return self.execute(Command.FIND_ELEMENT, {
  File "c:\users\kai\pycharmprojects\pythonproject\venv\lib\site-packages\selenium\webdriver\remote\webdriver.py", line 321, in execute
    self.error_handler.check_response(response)
  File "c:\users\kai\pycharmprojects\pythonproject\venv\lib\site-packages\selenium\webdriver\remote\errorhandler.py", line 242, in check_response
    raise exception_class(message, screen, stacktrace)
selenium.common.exceptions.NoSuchElementException: Message: no such element: Unable to locate element: {"method":"xpath","selector":"//div[@id='drawer-content-layout']//div[contains(@class,'deepsearch-content')]//div[@id='info-list']//div[contains(@class,'search-company-info-view')]/div[contains(@class,'company-info-header')]/a"}
  (Session info: chrome=91.0.4472.164)



2021-07-22 02:30:20_000815_삼성화재우
Traceback (most recent call last):
  File "C:\Users\kai\PycharmProjects\pythonProject\noname\noname\spiders\report_spider.py", line 144, in document_scraping
    button = self.driver.find_element_by_xpath(
  File "c:\users\kai\pycharmprojects\pythonproject\venv\lib\site-packages\selenium\webdriver\remote\webdriver.py", line 394, in find_element_by_xpath
    return self.find_element(by=By.XPATH, value=xpath)
  File "c:\users\kai\pycharmprojects\pythonproject\venv\lib\site-packages\selenium\webdriver\remote\webdriver.py", line 976, in find_element
    return self.execute(Command.FIND_ELEMENT, {
  File "c:\users\kai\pycharmprojects\pythonproject\venv\lib\site-packages\selenium\webdriver\remote\webdriver.py", line 321, in execute
    self.error_handler.check_response(response)
  File "c:\users\kai\pycharmprojects\pythonproject\venv\lib\site-packages\selenium\webdriver\remote\errorhandler.py", line 242, in check_response
    raise exception_class(message, screen, stacktrace)
selenium.common.exceptions.NoSuchElementException: Message: no such element: Unable to locate element: {"method":"xpath","selector":"//div[@id='drawer-content-layout']//div[contains(@class,'deepsearch-content')]//div[@id='info-list']//div[contains(@class,'search-company-info-view')]/div[contains(@class,'company-info-header')]/a"}
  (Session info: chrome=91.0.4472.164)



2021-07-22 03:41:00_000885_한화우
Traceback (most recent call last):
  File "C:\Users\kai\PycharmProjects\pythonProject\noname\noname\spiders\report_spider.py", line 144, in document_scraping
    button = self.driver.find_element_by_xpath(
  File "c:\users\kai\pycharmprojects\pythonproject\venv\lib\site-packages\selenium\webdriver\remote\webdriver.py", line 394, in find_element_by_xpath
    return self.find_element(by=By.XPATH, value=xpath)
  File "c:\users\kai\pycharmprojects\pythonproject\venv\lib\site-packages\selenium\webdriver\remote\webdriver.py", line 976, in find_element
    return self.execute(Command.FIND_ELEMENT, {
  File "c:\users\kai\pycharmprojects\pythonproject\venv\lib\site-packages\selenium\webdriver\remote\webdriver.py", line 321, in execute
    self.error_handler.check_response(response)
  File "c:\users\kai\pycharmprojects\pythonproject\venv\lib\site-packages\selenium\webdriver\remote\errorhandler.py", line 242, in check_response
    raise exception_class(message, screen, stacktrace)
selenium.common.exceptions.NoSuchElementException: Message: no such element: Unable to locate element: {"method":"xpath","selector":"//div[@id='drawer-content-layout']//div[contains(@class,'deepsearch-content')]//div[@id='info-list']//div[contains(@class,'search-company-info-view')]/div[contains(@class,'company-info-header')]/a"}
  (Session info: chrome=91.0.4472.164)



2021-07-22 03:42:00_00088K_한화3우B
Traceback (most recent call last):
  File "C:\Users\kai\PycharmProjects\pythonProject\noname\noname\spiders\report_spider.py", line 144, in document_scraping
    button = self.driver.find_element_by_xpath(
  File "c:\users\kai\pycharmprojects\pythonproject\venv\lib\site-packages\selenium\webdriver\remote\webdriver.py", line 394, in find_element_by_xpath
    return self.find_element(by=By.XPATH, value=xpath)
  File "c:\users\kai\pycharmprojects\pythonproject\venv\lib\site-packages\selenium\webdriver\remote\webdriver.py", line 976, in find_element
    return self.execute(Command.FIND_ELEMENT, {
  File "c:\users\kai\pycharmprojects\pythonproject\venv\lib\site-packages\selenium\webdriver\remote\webdriver.py", line 321, in execute
    self.error_handler.check_response(response)
  File "c:\users\kai\pycharmprojects\pythonproject\venv\lib\site-packages\selenium\webdriver\remote\errorhandler.py", line 242, in check_response
    raise exception_class(message, screen, stacktrace)
selenium.common.exceptions.NoSuchElementException: Message: no such element: Unable to locate element: {"method":"xpath","selector":"//div[@id='drawer-content-layout']//div[contains(@class,'deepsearch-content')]//div[@id='info-list']//div[contains(@class,'search-company-info-view')]/div[contains(@class,'company-info-header')]/a"}
  (Session info: chrome=91.0.4472.164)



2021-07-22 04:23:25_000995_DB하이텍1우
Traceback (most recent call last):
  File "C:\Users\kai\PycharmProjects\pythonProject\noname\noname\spiders\report_spider.py", line 144, in document_scraping
    button = self.driver.find_element_by_xpath(
  File "c:\users\kai\pycharmprojects\pythonproject\venv\lib\site-packages\selenium\webdriver\remote\webdriver.py", line 394, in find_element_by_xpath
    return self.find_element(by=By.XPATH, value=xpath)
  File "c:\users\kai\pycharmprojects\pythonproject\venv\lib\site-packages\selenium\webdriver\remote\webdriver.py", line 976, in find_element
    return self.execute(Command.FIND_ELEMENT, {
  File "c:\users\kai\pycharmprojects\pythonproject\venv\lib\site-packages\selenium\webdriver\remote\webdriver.py", line 321, in execute
    self.error_handler.check_response(response)
  File "c:\users\kai\pycharmprojects\pythonproject\venv\lib\site-packages\selenium\webdriver\remote\errorhandler.py", line 242, in check_response
    raise exception_class(message, screen, stacktrace)
selenium.common.exceptions.NoSuchElementException: Message: no such element: Unable to locate element: {"method":"xpath","selector":"//div[@id='drawer-content-layout']//div[contains(@class,'deepsearch-content')]//div[@id='info-list']//div[contains(@class,'search-company-info-view')]/div[contains(@class,'company-info-header')]/a"}
  (Session info: chrome=91.0.4472.164)



2021-07-22 05:56:01_001045_CJ우
Traceback (most recent call last):
  File "C:\Users\kai\PycharmProjects\pythonProject\noname\noname\spiders\report_spider.py", line 144, in document_scraping
    button = self.driver.find_element_by_xpath(
  File "c:\users\kai\pycharmprojects\pythonproject\venv\lib\site-packages\selenium\webdriver\remote\webdriver.py", line 394, in find_element_by_xpath
    return self.find_element(by=By.XPATH, value=xpath)
  File "c:\users\kai\pycharmprojects\pythonproject\venv\lib\site-packages\selenium\webdriver\remote\webdriver.py", line 976, in find_element
    return self.execute(Command.FIND_ELEMENT, {
  File "c:\users\kai\pycharmprojects\pythonproject\venv\lib\site-packages\selenium\webdriver\remote\webdriver.py", line 321, in execute
    self.error_handler.check_response(response)
  File "c:\users\kai\pycharmprojects\pythonproject\venv\lib\site-packages\selenium\webdriver\remote\errorhandler.py", line 242, in check_response
    raise exception_class(message, screen, stacktrace)
selenium.common.exceptions.NoSuchElementException: Message: no such element: Unable to locate element: {"method":"xpath","selector":"//div[@id='drawer-content-layout']//div[contains(@class,'deepsearch-content')]//div[@id='info-list']//div[contains(@class,'search-company-info-view')]/div[contains(@class,'company-info-header')]/a"}
  (Session info: chrome=91.0.4472.164)



2021-07-22 05:56:59_00104K_CJ4우(전환)
Traceback (most recent call last):
  File "C:\Users\kai\PycharmProjects\pythonProject\noname\noname\spiders\report_spider.py", line 144, in document_scraping
    button = self.driver.find_element_by_xpath(
  File "c:\users\kai\pycharmprojects\pythonproject\venv\lib\site-packages\selenium\webdriver\remote\webdriver.py", line 394, in find_element_by_xpath
    return self.find_element(by=By.XPATH, value=xpath)
  File "c:\users\kai\pycharmprojects\pythonproject\venv\lib\site-packages\selenium\webdriver\remote\webdriver.py", line 976, in find_element
    return self.execute(Command.FIND_ELEMENT, {
  File "c:\users\kai\pycharmprojects\pythonproject\venv\lib\site-packages\selenium\webdriver\remote\webdriver.py", line 321, in execute
    self.error_handler.check_response(response)
  File "c:\users\kai\pycharmprojects\pythonproject\venv\lib\site-packages\selenium\webdriver\remote\errorhandler.py", line 242, in check_response
    raise exception_class(message, screen, stacktrace)
selenium.common.exceptions.NoSuchElementException: Message: no such element: Unable to locate element: {"method":"xpath","selector":"//div[@id='drawer-content-layout']//div[contains(@class,'deepsearch-content')]//div[@id='info-list']//div[contains(@class,'search-company-info-view')]/div[contains(@class,'company-info-header')]/a"}
  (Session info: chrome=91.0.4472.164)



2021-07-22 06:10:23_001065_JW중외제약우
Traceback (most recent call last):
  File "C:\Users\kai\PycharmProjects\pythonProject\noname\noname\spiders\report_spider.py", line 144, in document_scraping
    button = self.driver.find_element_by_xpath(
  File "c:\users\kai\pycharmprojects\pythonproject\venv\lib\site-packages\selenium\webdriver\remote\webdriver.py", line 394, in find_element_by_xpath
    return self.find_element(by=By.XPATH, value=xpath)
  File "c:\users\kai\pycharmprojects\pythonproject\venv\lib\site-packages\selenium\webdriver\remote\webdriver.py", line 976, in find_element
    return self.execute(Command.FIND_ELEMENT, {
  File "c:\users\kai\pycharmprojects\pythonproject\venv\lib\site-packages\selenium\webdriver\remote\webdriver.py", line 321, in execute
    self.error_handler.check_response(response)
  File "c:\users\kai\pycharmprojects\pythonproject\venv\lib\site-packages\selenium\webdriver\remote\errorhandler.py", line 242, in check_response
    raise exception_class(message, screen, stacktrace)
selenium.common.exceptions.NoSuchElementException: Message: no such element: Unable to locate element: {"method":"xpath","selector":"//div[@id='drawer-content-layout']//div[contains(@class,'deepsearch-content')]//div[@id='info-list']//div[contains(@class,'search-company-info-view')]/div[contains(@class,'company-info-header')]/a"}
  (Session info: chrome=91.0.4472.164)



2021-07-22 06:11:23_001067_JW중외제약2우B
Traceback (most recent call last):
  File "C:\Users\kai\PycharmProjects\pythonProject\noname\noname\spiders\report_spider.py", line 144, in document_scraping
    button = self.driver.find_element_by_xpath(
  File "c:\users\kai\pycharmprojects\pythonproject\venv\lib\site-packages\selenium\webdriver\remote\webdriver.py", line 394, in find_element_by_xpath
    return self.find_element(by=By.XPATH, value=xpath)
  File "c:\users\kai\pycharmprojects\pythonproject\venv\lib\site-packages\selenium\webdriver\remote\webdriver.py", line 976, in find_element
    return self.execute(Command.FIND_ELEMENT, {
  File "c:\users\kai\pycharmprojects\pythonproject\venv\lib\site-packages\selenium\webdriver\remote\webdriver.py", line 321, in execute
    self.error_handler.check_response(response)
  File "c:\users\kai\pycharmprojects\pythonproject\venv\lib\site-packages\selenium\webdriver\remote\errorhandler.py", line 242, in check_response
    raise exception_class(message, screen, stacktrace)
selenium.common.exceptions.NoSuchElementException: Message: no such element: Unable to locate element: {"method":"xpath","selector":"//div[@id='drawer-content-layout']//div[contains(@class,'deepsearch-content')]//div[@id='info-list']//div[contains(@class,'search-company-info-view')]/div[contains(@class,'company-info-header')]/a"}
  (Session info: chrome=91.0.4472.164)



2021-07-22 09:02:13_001275_부국증권우
Traceback (most recent call last):
  File "C:\Users\kai\PycharmProjects\pythonProject\noname\noname\spiders\report_spider.py", line 144, in document_scraping
    button = self.driver.find_element_by_xpath(
  File "c:\users\kai\pycharmprojects\pythonproject\venv\lib\site-packages\selenium\webdriver\remote\webdriver.py", line 394, in find_element_by_xpath
    return self.find_element(by=By.XPATH, value=xpath)
  File "c:\users\kai\pycharmprojects\pythonproject\venv\lib\site-packages\selenium\webdriver\remote\webdriver.py", line 976, in find_element
    return self.execute(Command.FIND_ELEMENT, {
  File "c:\users\kai\pycharmprojects\pythonproject\venv\lib\site-packages\selenium\webdriver\remote\webdriver.py", line 321, in execute
    self.error_handler.check_response(response)
  File "c:\users\kai\pycharmprojects\pythonproject\venv\lib\site-packages\selenium\webdriver\remote\errorhandler.py", line 242, in check_response
    raise exception_class(message, screen, stacktrace)
selenium.common.exceptions.NoSuchElementException: Message: no such element: Unable to locate element: {"method":"xpath","selector":"//div[@id='drawer-content-layout']//div[contains(@class,'deepsearch-content')]//div[@id='info-list']//div[contains(@class,'search-company-info-view')]/div[contains(@class,'company-info-header')]/a"}
  (Session info: chrome=91.0.4472.164)



2021-07-22 09:23:37_001390_KG케미칼
Traceback (most recent call last):
  File "C:\Users\kai\PycharmProjects\pythonProject\noname\noname\spiders\report_spider.py", line 200, in document_scraping
    total_document_count = self.driver.find_element_by_xpath(document_div_xpath +
IndexError: list index out of range

2021-07-22 09:42:58_001430_세아베스틸_Steel-철강 가격이 가리키는 업황 방향에 주목-01/11/2017
Traceback (most recent call last):
  File "C:\Users\kai\PycharmProjects\pythonProject\noname\noname\spiders\report_spider.py", line 263, in document_scraping
    os.rename(
PermissionError: [WinError 32] 다른 프로세스가 파일을 사용 중이기 때문에 프로세스가 액세스 할 수 없습니다: 'C:/Users/kai/Desktop/korean_stock_document_list/temp_document/000-601e0ffb42db607b1acc32a98a6803be301c538c.pdf.crdownload' -> 'C:/Users/kai/Desktop/korean_stock_document_list/list/001430_세아베스틸/report/0083_Steel-철강_가격이_가리키는_업황_방향에_주목-01_11_2017.crdownload'

2021-07-22 10:40:35_001450_현대해상
Traceback (most recent call last):
  File "C:\Users\kai\PycharmProjects\pythonProject\noname\noname\spiders\report_spider.py", line 317, in document_scraping
    self.document_complete_list.to_excel(
  File "c:\users\kai\pycharmprojects\pythonproject\venv\lib\site-packages\pandas\core\generic.py", line 2189, in to_excel
    formatter.write(
  File "c:\users\kai\pycharmprojects\pythonproject\venv\lib\site-packages\pandas\io\formats\excel.py", line 815, in write
    writer = ExcelWriter(  # type: ignore[abstract]
  File "c:\users\kai\pycharmprojects\pythonproject\venv\lib\site-packages\pandas\io\excel\_openpyxl.py", line 32, in __init__
    super().__init__(
  File "c:\users\kai\pycharmprojects\pythonproject\venv\lib\site-packages\pandas\io\excel\_base.py", line 810, in __init__
    self.handles = get_handle(
  File "c:\users\kai\pycharmprojects\pythonproject\venv\lib\site-packages\pandas\io\common.py", line 651, in get_handle
    handle = open(handle, ioargs.mode)
PermissionError: [Errno 13] Permission denied: 'C:/Users/kai/Desktop/korean_stock_document_list/document_complete_list.xlsx'


2021-07-22 10:43:31_001450_현대해상
Traceback (most recent call last):
  File "c:\users\kai\pycharmprojects\pythonproject\venv\lib\site-packages\urllib3\connection.py", line 169, in _new_conn
    conn = connection.create_connection(
  File "c:\users\kai\pycharmprojects\pythonproject\venv\lib\site-packages\urllib3\util\connection.py", line 96, in create_connection
    raise err
  File "c:\users\kai\pycharmprojects\pythonproject\venv\lib\site-packages\urllib3\util\connection.py", line 86, in create_connection
    sock.connect(sa)
ConnectionRefusedError: [WinError 10061] 대상 컴퓨터에서 연결을 거부했으므로 연결하지 못했습니다

During handling of the above exception, another exception occurred:

Traceback (most recent call last):
  File "c:\users\kai\pycharmprojects\pythonproject\venv\lib\site-packages\urllib3\connectionpool.py", line 699, in urlopen
    httplib_response = self._make_request(
  File "c:\users\kai\pycharmprojects\pythonproject\venv\lib\site-packages\urllib3\connectionpool.py", line 394, in _make_request
    conn.request(method, url, **httplib_request_kw)
  File "c:\users\kai\pycharmprojects\pythonproject\venv\lib\site-packages\urllib3\connection.py", line 234, in request
    super(HTTPConnection, self).request(method, url, body=body, headers=headers)
  File "C:\Users\kai\AppData\Local\Programs\Python\Python39\lib\http\client.py", line 1253, in request
    self._send_request(method, url, body, headers, encode_chunked)
  File "C:\Users\kai\AppData\Local\Programs\Python\Python39\lib\http\client.py", line 1299, in _send_request
    self.endheaders(body, encode_chunked=encode_chunked)
  File "C:\Users\kai\AppData\Local\Programs\Python\Python39\lib\http\client.py", line 1248, in endheaders
    self._send_output(message_body, encode_chunked=encode_chunked)
  File "C:\Users\kai\AppData\Local\Programs\Python\Python39\lib\http\client.py", line 1008, in _send_output
    self.send(msg)
  File "C:\Users\kai\AppData\Local\Programs\Python\Python39\lib\http\client.py", line 948, in send
    self.connect()
  File "c:\users\kai\pycharmprojects\pythonproject\venv\lib\site-packages\urllib3\connection.py", line 200, in connect
    conn = self._new_conn()
  File "c:\users\kai\pycharmprojects\pythonproject\venv\lib\site-packages\urllib3\connection.py", line 181, in _new_conn
    raise NewConnectionError(
urllib3.exceptions.NewConnectionError: <urllib3.connection.HTTPConnection object at 0x000001635CA76070>: Failed to establish a new connection: [WinError 10061] 대상 컴퓨터에서 연결을 거부했으므로 연결하지 못했습니다

During handling of the above exception, another exception occurred:

Traceback (most recent call last):
  File "C:\Users\kai\PycharmProjects\pythonProject\noname\noname\spiders\report_spider.py", line 220, in document_scraping
    document_list = self.driver.find_elements_by_xpath(document_div_xpath +
  File "c:\users\kai\pycharmprojects\pythonproject\venv\lib\site-packages\selenium\webdriver\remote\webdriver.py", line 410, in find_elements_by_xpath
    return self.find_elements(by=By.XPATH, value=xpath)
  File "c:\users\kai\pycharmprojects\pythonproject\venv\lib\site-packages\selenium\webdriver\remote\webdriver.py", line 1005, in find_elements
    return self.execute(Command.FIND_ELEMENTS, {
  File "c:\users\kai\pycharmprojects\pythonproject\venv\lib\site-packages\selenium\webdriver\remote\webdriver.py", line 319, in execute
    response = self.command_executor.execute(driver_command, params)
  File "c:\users\kai\pycharmprojects\pythonproject\venv\lib\site-packages\selenium\webdriver\remote\remote_connection.py", line 374, in execute
    return self._request(command_info[0], url, body=data)
  File "c:\users\kai\pycharmprojects\pythonproject\venv\lib\site-packages\selenium\webdriver\remote\remote_connection.py", line 397, in _request
    resp = self._conn.request(method, url, body=body, headers=headers)
  File "c:\users\kai\pycharmprojects\pythonproject\venv\lib\site-packages\urllib3\request.py", line 78, in request
    return self.request_encode_body(
  File "c:\users\kai\pycharmprojects\pythonproject\venv\lib\site-packages\urllib3\request.py", line 170, in request_encode_body
    return self.urlopen(method, url, **extra_kw)
  File "c:\users\kai\pycharmprojects\pythonproject\venv\lib\site-packages\urllib3\poolmanager.py", line 375, in urlopen
    response = conn.urlopen(method, u.request_uri, **kw)
  File "c:\users\kai\pycharmprojects\pythonproject\venv\lib\site-packages\urllib3\connectionpool.py", line 783, in urlopen
    return self.urlopen(
  File "c:\users\kai\pycharmprojects\pythonproject\venv\lib\site-packages\urllib3\connectionpool.py", line 783, in urlopen
    return self.urlopen(
  File "c:\users\kai\pycharmprojects\pythonproject\venv\lib\site-packages\urllib3\connectionpool.py", line 783, in urlopen
    return self.urlopen(
  File "c:\users\kai\pycharmprojects\pythonproject\venv\lib\site-packages\urllib3\connectionpool.py", line 755, in urlopen
    retries = retries.increment(
  File "c:\users\kai\pycharmprojects\pythonproject\venv\lib\site-packages\urllib3\util\retry.py", line 574, in increment
    raise MaxRetryError(_pool, url, error or ResponseError(cause))
urllib3.exceptions.MaxRetryError: HTTPConnectionPool(host='127.0.0.1', port=61276): Max retries exceeded with url: /session/554c18541e9f0e3d3fde7d9f0b51909e/elements (Caused by NewConnectionError('<urllib3.connection.HTTPConnection object at 0x000001635CA76070>: Failed to establish a new connection: [WinError 10061] 대상 컴퓨터에서 연결을 거부했으므로 연결하지 못했습니다'))


2021-07-22 10:43:39_001450_현대해상
Traceback (most recent call last):
  File "c:\users\kai\pycharmprojects\pythonproject\venv\lib\site-packages\urllib3\connection.py", line 169, in _new_conn
    conn = connection.create_connection(
  File "c:\users\kai\pycharmprojects\pythonproject\venv\lib\site-packages\urllib3\util\connection.py", line 96, in create_connection
    raise err
  File "c:\users\kai\pycharmprojects\pythonproject\venv\lib\site-packages\urllib3\util\connection.py", line 86, in create_connection
    sock.connect(sa)
ConnectionRefusedError: [WinError 10061] 대상 컴퓨터에서 연결을 거부했으므로 연결하지 못했습니다

During handling of the above exception, another exception occurred:

Traceback (most recent call last):
  File "c:\users\kai\pycharmprojects\pythonproject\venv\lib\site-packages\urllib3\connectionpool.py", line 699, in urlopen
    httplib_response = self._make_request(
  File "c:\users\kai\pycharmprojects\pythonproject\venv\lib\site-packages\urllib3\connectionpool.py", line 394, in _make_request
    conn.request(method, url, **httplib_request_kw)
  File "c:\users\kai\pycharmprojects\pythonproject\venv\lib\site-packages\urllib3\connection.py", line 234, in request
    super(HTTPConnection, self).request(method, url, body=body, headers=headers)
  File "C:\Users\kai\AppData\Local\Programs\Python\Python39\lib\http\client.py", line 1253, in request
    self._send_request(method, url, body, headers, encode_chunked)
  File "C:\Users\kai\AppData\Local\Programs\Python\Python39\lib\http\client.py", line 1299, in _send_request
    self.endheaders(body, encode_chunked=encode_chunked)
  File "C:\Users\kai\AppData\Local\Programs\Python\Python39\lib\http\client.py", line 1248, in endheaders
    self._send_output(message_body, encode_chunked=encode_chunked)
  File "C:\Users\kai\AppData\Local\Programs\Python\Python39\lib\http\client.py", line 1008, in _send_output
    self.send(msg)
  File "C:\Users\kai\AppData\Local\Programs\Python\Python39\lib\http\client.py", line 948, in send
    self.connect()
  File "c:\users\kai\pycharmprojects\pythonproject\venv\lib\site-packages\urllib3\connection.py", line 200, in connect
    conn = self._new_conn()
  File "c:\users\kai\pycharmprojects\pythonproject\venv\lib\site-packages\urllib3\connection.py", line 181, in _new_conn
    raise NewConnectionError(
urllib3.exceptions.NewConnectionError: <urllib3.connection.HTTPConnection object at 0x000001635CBBC8B0>: Failed to establish a new connection: [WinError 10061] 대상 컴퓨터에서 연결을 거부했으므로 연결하지 못했습니다

During handling of the above exception, another exception occurred:

Traceback (most recent call last):
  File "C:\Users\kai\PycharmProjects\pythonProject\noname\noname\spiders\report_spider.py", line 123, in document_scraping
    menu1_button = self.driver.find_element_by_xpath(
  File "c:\users\kai\pycharmprojects\pythonproject\venv\lib\site-packages\selenium\webdriver\remote\webdriver.py", line 394, in find_element_by_xpath
    return self.find_element(by=By.XPATH, value=xpath)
  File "c:\users\kai\pycharmprojects\pythonproject\venv\lib\site-packages\selenium\webdriver\remote\webdriver.py", line 976, in find_element
    return self.execute(Command.FIND_ELEMENT, {
  File "c:\users\kai\pycharmprojects\pythonproject\venv\lib\site-packages\selenium\webdriver\remote\webdriver.py", line 319, in execute
    response = self.command_executor.execute(driver_command, params)
  File "c:\users\kai\pycharmprojects\pythonproject\venv\lib\site-packages\selenium\webdriver\remote\remote_connection.py", line 374, in execute
    return self._request(command_info[0], url, body=data)
  File "c:\users\kai\pycharmprojects\pythonproject\venv\lib\site-packages\selenium\webdriver\remote\remote_connection.py", line 397, in _request
    resp = self._conn.request(method, url, body=body, headers=headers)
  File "c:\users\kai\pycharmprojects\pythonproject\venv\lib\site-packages\urllib3\request.py", line 78, in request
    return self.request_encode_body(
  File "c:\users\kai\pycharmprojects\pythonproject\venv\lib\site-packages\urllib3\request.py", line 170, in request_encode_body
    return self.urlopen(method, url, **extra_kw)
  File "c:\users\kai\pycharmprojects\pythonproject\venv\lib\site-packages\urllib3\poolmanager.py", line 375, in urlopen
    response = conn.urlopen(method, u.request_uri, **kw)
  File "c:\users\kai\pycharmprojects\pythonproject\venv\lib\site-packages\urllib3\connectionpool.py", line 783, in urlopen
    return self.urlopen(
  File "c:\users\kai\pycharmprojects\pythonproject\venv\lib\site-packages\urllib3\connectionpool.py", line 783, in urlopen
    return self.urlopen(
  File "c:\users\kai\pycharmprojects\pythonproject\venv\lib\site-packages\urllib3\connectionpool.py", line 783, in urlopen
    return self.urlopen(
  File "c:\users\kai\pycharmprojects\pythonproject\venv\lib\site-packages\urllib3\connectionpool.py", line 755, in urlopen
    retries = retries.increment(
  File "c:\users\kai\pycharmprojects\pythonproject\venv\lib\site-packages\urllib3\util\retry.py", line 574, in increment
    raise MaxRetryError(_pool, url, error or ResponseError(cause))
urllib3.exceptions.MaxRetryError: HTTPConnectionPool(host='127.0.0.1', port=61276): Max retries exceeded with url: /session/554c18541e9f0e3d3fde7d9f0b51909e/element (Caused by NewConnectionError('<urllib3.connection.HTTPConnection object at 0x000001635CBBC8B0>: Failed to establish a new connection: [WinError 10061] 대상 컴퓨터에서 연결을 거부했으므로 연결하지 못했습니다'))

