2021-07-15 13:36_061970_엘비세미콘
Traceback (most recent call last):
  File "C:\Users\kai\PycharmProjects\pythonProject\noname\noname\spiders\noname_spider.py", line 274, in company_scrapy
    button = self.driver.find_element_by_xpath(
  File "c:\users\kai\pycharmprojects\pythonproject\venv\lib\site-packages\selenium\webdriver\remote\webdriver.py", line 394, in find_element_by_xpath
    return self.find_element(by=By.XPATH, value=xpath)
  File "c:\users\kai\pycharmprojects\pythonproject\venv\lib\site-packages\selenium\webdriver\remote\webdriver.py", line 976, in find_element
    return self.execute(Command.FIND_ELEMENT, {
  File "c:\users\kai\pycharmprojects\pythonproject\venv\lib\site-packages\selenium\webdriver\remote\webdriver.py", line 321, in execute
    self.error_handler.check_response(response)
  File "c:\users\kai\pycharmprojects\pythonproject\venv\lib\site-packages\selenium\webdriver\remote\errorhandler.py", line 242, in check_response
    raise exception_class(message, screen, stacktrace)
selenium.common.exceptions.NoSuchElementException: Message: no such element: Unable to locate element: {"method":"xpath","selector":"//div[@id='root']/div/div[contains(@class,'deepsesarch-dropdown-items')]/div[1]"}
  (Session info: chrome=91.0.4472.124)

2021-07-15 13:50_065370_위세아이텍
Traceback (most recent call last):
  File "C:\Users\kai\PycharmProjects\pythonProject\noname\noname\spiders\noname_spider.py", line 274, in company_scrapy
    button = self.driver.find_element_by_xpath(
  File "c:\users\kai\pycharmprojects\pythonproject\venv\lib\site-packages\selenium\webdriver\remote\webdriver.py", line 394, in find_element_by_xpath
    return self.find_element(by=By.XPATH, value=xpath)
  File "c:\users\kai\pycharmprojects\pythonproject\venv\lib\site-packages\selenium\webdriver\remote\webdriver.py", line 976, in find_element
    return self.execute(Command.FIND_ELEMENT, {
  File "c:\users\kai\pycharmprojects\pythonproject\venv\lib\site-packages\selenium\webdriver\remote\webdriver.py", line 321, in execute
    self.error_handler.check_response(response)
  File "c:\users\kai\pycharmprojects\pythonproject\venv\lib\site-packages\selenium\webdriver\remote\errorhandler.py", line 242, in check_response
    raise exception_class(message, screen, stacktrace)
selenium.common.exceptions.NoSuchElementException: Message: no such element: Unable to locate element: {"method":"xpath","selector":"//div[@id='root']/div/div[contains(@class,'deepsesarch-dropdown-items')]/div[1]"}
  (Session info: chrome=91.0.4472.124)

2021-07-15 13:57_065500_오리엔트정공
Traceback (most recent call last):
  File "C:\Users\kai\PycharmProjects\pythonProject\noname\noname\spiders\noname_spider.py", line 274, in company_scrapy
    button = self.driver.find_element_by_xpath(
  File "c:\users\kai\pycharmprojects\pythonproject\venv\lib\site-packages\selenium\webdriver\remote\webdriver.py", line 394, in find_element_by_xpath
    return self.find_element(by=By.XPATH, value=xpath)
  File "c:\users\kai\pycharmprojects\pythonproject\venv\lib\site-packages\selenium\webdriver\remote\webdriver.py", line 976, in find_element
    return self.execute(Command.FIND_ELEMENT, {
  File "c:\users\kai\pycharmprojects\pythonproject\venv\lib\site-packages\selenium\webdriver\remote\webdriver.py", line 321, in execute
    self.error_handler.check_response(response)
  File "c:\users\kai\pycharmprojects\pythonproject\venv\lib\site-packages\selenium\webdriver\remote\errorhandler.py", line 242, in check_response
    raise exception_class(message, screen, stacktrace)
selenium.common.exceptions.NoSuchElementException: Message: no such element: Unable to locate element: {"method":"xpath","selector":"//div[@id='root']/div/div[contains(@class,'deepsesarch-dropdown-items')]/div[1]"}
  (Session info: chrome=91.0.4472.124)

2021-07-15 14:29_066670_디스플레이텍
Traceback (most recent call last):
  File "C:\Users\kai\PycharmProjects\pythonProject\noname\noname\spiders\noname_spider.py", line 274, in company_scrapy
    button = self.driver.find_element_by_xpath(
  File "c:\users\kai\pycharmprojects\pythonproject\venv\lib\site-packages\selenium\webdriver\remote\webdriver.py", line 394, in find_element_by_xpath
    return self.find_element(by=By.XPATH, value=xpath)
  File "c:\users\kai\pycharmprojects\pythonproject\venv\lib\site-packages\selenium\webdriver\remote\webdriver.py", line 976, in find_element
    return self.execute(Command.FIND_ELEMENT, {
  File "c:\users\kai\pycharmprojects\pythonproject\venv\lib\site-packages\selenium\webdriver\remote\webdriver.py", line 321, in execute
    self.error_handler.check_response(response)
  File "c:\users\kai\pycharmprojects\pythonproject\venv\lib\site-packages\selenium\webdriver\remote\errorhandler.py", line 242, in check_response
    raise exception_class(message, screen, stacktrace)
selenium.common.exceptions.NoSuchElementException: Message: no such element: Unable to locate element: {"method":"xpath","selector":"//div[@id='root']/div/div[contains(@class,'deepsesarch-dropdown-items')]/div[1]"}
  (Session info: chrome=91.0.4472.124)

2021-07-15 14:34_066830_제노텍
Traceback (most recent call last):
  File "C:\Users\kai\PycharmProjects\pythonProject\noname\noname\spiders\noname_spider.py", line 274, in company_scrapy
    button = self.driver.find_element_by_xpath(
  File "c:\users\kai\pycharmprojects\pythonproject\venv\lib\site-packages\selenium\webdriver\remote\webdriver.py", line 394, in find_element_by_xpath
    return self.find_element(by=By.XPATH, value=xpath)
  File "c:\users\kai\pycharmprojects\pythonproject\venv\lib\site-packages\selenium\webdriver\remote\webdriver.py", line 976, in find_element
    return self.execute(Command.FIND_ELEMENT, {
  File "c:\users\kai\pycharmprojects\pythonproject\venv\lib\site-packages\selenium\webdriver\remote\webdriver.py", line 321, in execute
    self.error_handler.check_response(response)
  File "c:\users\kai\pycharmprojects\pythonproject\venv\lib\site-packages\selenium\webdriver\remote\errorhandler.py", line 242, in check_response
    raise exception_class(message, screen, stacktrace)
selenium.common.exceptions.NoSuchElementException: Message: no such element: Unable to locate element: {"method":"xpath","selector":"//div[@id='root']/div/div[contains(@class,'deepsesarch-dropdown-items')]/div[1]"}
  (Session info: chrome=91.0.4472.124)

2021-07-15 15:02_067990_도이치모터스
Traceback (most recent call last):
  File "C:\Users\kai\PycharmProjects\pythonProject\noname\noname\spiders\noname_spider.py", line 250, in company_scrapy
    button = self.driver.find_element_by_xpath(
  File "c:\users\kai\pycharmprojects\pythonproject\venv\lib\site-packages\selenium\webdriver\remote\webdriver.py", line 394, in find_element_by_xpath
    return self.find_element(by=By.XPATH, value=xpath)
  File "c:\users\kai\pycharmprojects\pythonproject\venv\lib\site-packages\selenium\webdriver\remote\webdriver.py", line 976, in find_element
    return self.execute(Command.FIND_ELEMENT, {
  File "c:\users\kai\pycharmprojects\pythonproject\venv\lib\site-packages\selenium\webdriver\remote\webdriver.py", line 321, in execute
    self.error_handler.check_response(response)
  File "c:\users\kai\pycharmprojects\pythonproject\venv\lib\site-packages\selenium\webdriver\remote\errorhandler.py", line 242, in check_response
    raise exception_class(message, screen, stacktrace)
selenium.common.exceptions.NoSuchElementException: Message: no such element: Unable to locate element: {"method":"xpath","selector":"//div[@id='income-statement']//div[contains(@class,'header-text')]//div[contains(@class,'options')]/div[1]/div"}
  (Session info: chrome=91.0.4472.124)

2021-07-15 15:04_067990_도이치모터스
Traceback (most recent call last):
  File "C:\Users\kai\PycharmProjects\pythonProject\noname\noname\spiders\noname_spider.py", line 283, in company_scrapy
    button = self.driver.find_element_by_xpath(
  File "c:\users\kai\pycharmprojects\pythonproject\venv\lib\site-packages\selenium\webdriver\remote\webdriver.py", line 394, in find_element_by_xpath
    return self.find_element(by=By.XPATH, value=xpath)
  File "c:\users\kai\pycharmprojects\pythonproject\venv\lib\site-packages\selenium\webdriver\remote\webdriver.py", line 976, in find_element
    return self.execute(Command.FIND_ELEMENT, {
  File "c:\users\kai\pycharmprojects\pythonproject\venv\lib\site-packages\selenium\webdriver\remote\webdriver.py", line 321, in execute
    self.error_handler.check_response(response)
  File "c:\users\kai\pycharmprojects\pythonproject\venv\lib\site-packages\selenium\webdriver\remote\errorhandler.py", line 242, in check_response
    raise exception_class(message, screen, stacktrace)
selenium.common.exceptions.NoSuchElementException: Message: no such element: Unable to locate element: {"method":"xpath","selector":"//div[@id='income-statement']//div[contains(@class,'table-container')]//span[@class='table-export-button']"}
  (Session info: chrome=91.0.4472.124)

2021-07-15 15:19_069330_유아이디
Traceback (most recent call last):
  File "C:\Users\kai\PycharmProjects\pythonProject\noname\noname\spiders\noname_spider.py", line 274, in company_scrapy
    button = self.driver.find_element_by_xpath(
  File "c:\users\kai\pycharmprojects\pythonproject\venv\lib\site-packages\selenium\webdriver\remote\webdriver.py", line 394, in find_element_by_xpath
    return self.find_element(by=By.XPATH, value=xpath)
  File "c:\users\kai\pycharmprojects\pythonproject\venv\lib\site-packages\selenium\webdriver\remote\webdriver.py", line 976, in find_element
    return self.execute(Command.FIND_ELEMENT, {
  File "c:\users\kai\pycharmprojects\pythonproject\venv\lib\site-packages\selenium\webdriver\remote\webdriver.py", line 321, in execute
    self.error_handler.check_response(response)
  File "c:\users\kai\pycharmprojects\pythonproject\venv\lib\site-packages\selenium\webdriver\remote\errorhandler.py", line 242, in check_response
    raise exception_class(message, screen, stacktrace)
selenium.common.exceptions.NoSuchElementException: Message: no such element: Unable to locate element: {"method":"xpath","selector":"//div[@id='root']/div/div[contains(@class,'deepsesarch-dropdown-items')]/div[1]"}
  (Session info: chrome=91.0.4472.124)

2021-07-15 15:32_071280_로체시스템즈
Traceback (most recent call last):
  File "C:\Users\kai\PycharmProjects\pythonProject\noname\noname\spiders\noname_spider.py", line 274, in company_scrapy
    button = self.driver.find_element_by_xpath(
  File "c:\users\kai\pycharmprojects\pythonproject\venv\lib\site-packages\selenium\webdriver\remote\webdriver.py", line 394, in find_element_by_xpath
    return self.find_element(by=By.XPATH, value=xpath)
  File "c:\users\kai\pycharmprojects\pythonproject\venv\lib\site-packages\selenium\webdriver\remote\webdriver.py", line 976, in find_element
    return self.execute(Command.FIND_ELEMENT, {
  File "c:\users\kai\pycharmprojects\pythonproject\venv\lib\site-packages\selenium\webdriver\remote\webdriver.py", line 321, in execute
    self.error_handler.check_response(response)
  File "c:\users\kai\pycharmprojects\pythonproject\venv\lib\site-packages\selenium\webdriver\remote\errorhandler.py", line 242, in check_response
    raise exception_class(message, screen, stacktrace)
selenium.common.exceptions.NoSuchElementException: Message: no such element: Unable to locate element: {"method":"xpath","selector":"//div[@id='root']/div/div[contains(@class,'deepsesarch-dropdown-items')]/div[1]"}
  (Session info: chrome=91.0.4472.124)

2021-07-15 15:47_072950_빛샘전자
Traceback (most recent call last):
  File "C:\Users\kai\PycharmProjects\pythonProject\noname\noname\spiders\noname_spider.py", line 274, in company_scrapy
    button = self.driver.find_element_by_xpath(
  File "c:\users\kai\pycharmprojects\pythonproject\venv\lib\site-packages\selenium\webdriver\remote\webdriver.py", line 394, in find_element_by_xpath
    return self.find_element(by=By.XPATH, value=xpath)
  File "c:\users\kai\pycharmprojects\pythonproject\venv\lib\site-packages\selenium\webdriver\remote\webdriver.py", line 976, in find_element
    return self.execute(Command.FIND_ELEMENT, {
  File "c:\users\kai\pycharmprojects\pythonproject\venv\lib\site-packages\selenium\webdriver\remote\webdriver.py", line 321, in execute
    self.error_handler.check_response(response)
  File "c:\users\kai\pycharmprojects\pythonproject\venv\lib\site-packages\selenium\webdriver\remote\errorhandler.py", line 242, in check_response
    raise exception_class(message, screen, stacktrace)
selenium.common.exceptions.NoSuchElementException: Message: no such element: Unable to locate element: {"method":"xpath","selector":"//div[@id='root']/div/div[contains(@class,'deepsesarch-dropdown-items')]/div[1]"}
  (Session info: chrome=91.0.4472.124)

2021-07-15 16:13_078020_이베스트투자증권
Traceback (most recent call last):
  File "C:\Users\kai\PycharmProjects\pythonProject\noname\noname\spiders\noname_spider.py", line 274, in company_scrapy
    button = self.driver.find_element_by_xpath(
  File "c:\users\kai\pycharmprojects\pythonproject\venv\lib\site-packages\selenium\webdriver\remote\webdriver.py", line 394, in find_element_by_xpath
    return self.find_element(by=By.XPATH, value=xpath)
  File "c:\users\kai\pycharmprojects\pythonproject\venv\lib\site-packages\selenium\webdriver\remote\webdriver.py", line 976, in find_element
    return self.execute(Command.FIND_ELEMENT, {
  File "c:\users\kai\pycharmprojects\pythonproject\venv\lib\site-packages\selenium\webdriver\remote\webdriver.py", line 321, in execute
    self.error_handler.check_response(response)
  File "c:\users\kai\pycharmprojects\pythonproject\venv\lib\site-packages\selenium\webdriver\remote\errorhandler.py", line 242, in check_response
    raise exception_class(message, screen, stacktrace)
selenium.common.exceptions.NoSuchElementException: Message: no such element: Unable to locate element: {"method":"xpath","selector":"//div[@id='root']/div/div[contains(@class,'deepsesarch-dropdown-items')]/div[1]"}
  (Session info: chrome=91.0.4472.124)

2021-07-15 16:17_078130_국일제지
Traceback (most recent call last):
  File "C:\Users\kai\PycharmProjects\pythonProject\noname\noname\spiders\noname_spider.py", line 274, in company_scrapy
    button = self.driver.find_element_by_xpath(
  File "c:\users\kai\pycharmprojects\pythonproject\venv\lib\site-packages\selenium\webdriver\remote\webdriver.py", line 394, in find_element_by_xpath
    return self.find_element(by=By.XPATH, value=xpath)
  File "c:\users\kai\pycharmprojects\pythonproject\venv\lib\site-packages\selenium\webdriver\remote\webdriver.py", line 976, in find_element
    return self.execute(Command.FIND_ELEMENT, {
  File "c:\users\kai\pycharmprojects\pythonproject\venv\lib\site-packages\selenium\webdriver\remote\webdriver.py", line 321, in execute
    self.error_handler.check_response(response)
  File "c:\users\kai\pycharmprojects\pythonproject\venv\lib\site-packages\selenium\webdriver\remote\errorhandler.py", line 242, in check_response
    raise exception_class(message, screen, stacktrace)
selenium.common.exceptions.NoSuchElementException: Message: no such element: Unable to locate element: {"method":"xpath","selector":"//div[@id='root']/div/div[contains(@class,'deepsesarch-dropdown-items')]/div[1]"}
  (Session info: chrome=91.0.4472.124)

2021-07-15 16:20_078150_HB테크놀러지
Traceback (most recent call last):
  File "C:\Users\kai\PycharmProjects\pythonProject\noname\noname\spiders\noname_spider.py", line 267, in company_scrapy
    button = self.driver.find_element_by_xpath(
  File "c:\users\kai\pycharmprojects\pythonproject\venv\lib\site-packages\selenium\webdriver\remote\webdriver.py", line 394, in find_element_by_xpath
    return self.find_element(by=By.XPATH, value=xpath)
  File "c:\users\kai\pycharmprojects\pythonproject\venv\lib\site-packages\selenium\webdriver\remote\webdriver.py", line 976, in find_element
    return self.execute(Command.FIND_ELEMENT, {
  File "c:\users\kai\pycharmprojects\pythonproject\venv\lib\site-packages\selenium\webdriver\remote\webdriver.py", line 321, in execute
    self.error_handler.check_response(response)
  File "c:\users\kai\pycharmprojects\pythonproject\venv\lib\site-packages\selenium\webdriver\remote\errorhandler.py", line 242, in check_response
    raise exception_class(message, screen, stacktrace)
selenium.common.exceptions.NoSuchElementException: Message: no such element: Unable to locate element: {"method":"xpath","selector":"//div[@id='income-statement']//div[contains(@class,'header-text')]//div[contains(@class,'options')]/div[contains(@class,'option')][2]/div[contains(@class,'dropdown-selected')]"}
  (Session info: chrome=91.0.4472.124)

2021-07-15 16:23_078350_한양디지텍
Traceback (most recent call last):
  File "C:\Users\kai\PycharmProjects\pythonProject\noname\noname\spiders\noname_spider.py", line 250, in company_scrapy
    button = self.driver.find_element_by_xpath(
  File "c:\users\kai\pycharmprojects\pythonproject\venv\lib\site-packages\selenium\webdriver\remote\webdriver.py", line 394, in find_element_by_xpath
    return self.find_element(by=By.XPATH, value=xpath)
  File "c:\users\kai\pycharmprojects\pythonproject\venv\lib\site-packages\selenium\webdriver\remote\webdriver.py", line 976, in find_element
    return self.execute(Command.FIND_ELEMENT, {
  File "c:\users\kai\pycharmprojects\pythonproject\venv\lib\site-packages\selenium\webdriver\remote\webdriver.py", line 321, in execute
    self.error_handler.check_response(response)
  File "c:\users\kai\pycharmprojects\pythonproject\venv\lib\site-packages\selenium\webdriver\remote\errorhandler.py", line 242, in check_response
    raise exception_class(message, screen, stacktrace)
selenium.common.exceptions.NoSuchElementException: Message: no such element: Unable to locate element: {"method":"xpath","selector":"//div[@id='income-statement']//div[contains(@class,'header-text')]//div[contains(@class,'options')]/div[1]/div"}
  (Session info: chrome=91.0.4472.124)

2021-07-15 16:24_078350_한양디지텍
Traceback (most recent call last):
  File "C:\Users\kai\PycharmProjects\pythonProject\noname\noname\spiders\noname_spider.py", line 250, in company_scrapy
    button = self.driver.find_element_by_xpath(
  File "c:\users\kai\pycharmprojects\pythonproject\venv\lib\site-packages\selenium\webdriver\remote\webdriver.py", line 394, in find_element_by_xpath
    return self.find_element(by=By.XPATH, value=xpath)
  File "c:\users\kai\pycharmprojects\pythonproject\venv\lib\site-packages\selenium\webdriver\remote\webdriver.py", line 976, in find_element
    return self.execute(Command.FIND_ELEMENT, {
  File "c:\users\kai\pycharmprojects\pythonproject\venv\lib\site-packages\selenium\webdriver\remote\webdriver.py", line 321, in execute
    self.error_handler.check_response(response)
  File "c:\users\kai\pycharmprojects\pythonproject\venv\lib\site-packages\selenium\webdriver\remote\errorhandler.py", line 242, in check_response
    raise exception_class(message, screen, stacktrace)
selenium.common.exceptions.NoSuchElementException: Message: no such element: Unable to locate element: {"method":"xpath","selector":"//div[@id='income-statement']//div[contains(@class,'header-text')]//div[contains(@class,'options')]/div[1]/div"}
  (Session info: chrome=91.0.4472.124)

2021-07-15 16:27_078590_OQP
Traceback (most recent call last):
  File "C:\Users\kai\PycharmProjects\pythonProject\noname\noname\spiders\noname_spider.py", line 274, in company_scrapy
    button = self.driver.find_element_by_xpath(
  File "c:\users\kai\pycharmprojects\pythonproject\venv\lib\site-packages\selenium\webdriver\remote\webdriver.py", line 394, in find_element_by_xpath
    return self.find_element(by=By.XPATH, value=xpath)
  File "c:\users\kai\pycharmprojects\pythonproject\venv\lib\site-packages\selenium\webdriver\remote\webdriver.py", line 976, in find_element
    return self.execute(Command.FIND_ELEMENT, {
  File "c:\users\kai\pycharmprojects\pythonproject\venv\lib\site-packages\selenium\webdriver\remote\webdriver.py", line 321, in execute
    self.error_handler.check_response(response)
  File "c:\users\kai\pycharmprojects\pythonproject\venv\lib\site-packages\selenium\webdriver\remote\errorhandler.py", line 242, in check_response
    raise exception_class(message, screen, stacktrace)
selenium.common.exceptions.NoSuchElementException: Message: no such element: Unable to locate element: {"method":"xpath","selector":"//div[@id='root']/div/div[contains(@class,'deepsesarch-dropdown-items')]/div[1]"}
  (Session info: chrome=91.0.4472.124)

2021-07-15 16:51_080000_에스엔유
Traceback (most recent call last):
  File "C:\Users\kai\PycharmProjects\pythonProject\noname\noname\spiders\noname_spider.py", line 274, in company_scrapy
    button = self.driver.find_element_by_xpath(
  File "c:\users\kai\pycharmprojects\pythonproject\venv\lib\site-packages\selenium\webdriver\remote\webdriver.py", line 394, in find_element_by_xpath
    return self.find_element(by=By.XPATH, value=xpath)
  File "c:\users\kai\pycharmprojects\pythonproject\venv\lib\site-packages\selenium\webdriver\remote\webdriver.py", line 976, in find_element
    return self.execute(Command.FIND_ELEMENT, {
  File "c:\users\kai\pycharmprojects\pythonproject\venv\lib\site-packages\selenium\webdriver\remote\webdriver.py", line 321, in execute
    self.error_handler.check_response(response)
  File "c:\users\kai\pycharmprojects\pythonproject\venv\lib\site-packages\selenium\webdriver\remote\errorhandler.py", line 242, in check_response
    raise exception_class(message, screen, stacktrace)
selenium.common.exceptions.NoSuchElementException: Message: no such element: Unable to locate element: {"method":"xpath","selector":"//div[@id='root']/div/div[contains(@class,'deepsesarch-dropdown-items')]/div[1]"}
  (Session info: chrome=91.0.4472.124)

2021-07-15 16:54_080160_모두투어
Traceback (most recent call last):
  File "C:\Users\kai\PycharmProjects\pythonProject\noname\noname\spiders\noname_spider.py", line 250, in company_scrapy
    button = self.driver.find_element_by_xpath(
  File "c:\users\kai\pycharmprojects\pythonproject\venv\lib\site-packages\selenium\webdriver\remote\webdriver.py", line 394, in find_element_by_xpath
    return self.find_element(by=By.XPATH, value=xpath)
  File "c:\users\kai\pycharmprojects\pythonproject\venv\lib\site-packages\selenium\webdriver\remote\webdriver.py", line 976, in find_element
    return self.execute(Command.FIND_ELEMENT, {
  File "c:\users\kai\pycharmprojects\pythonproject\venv\lib\site-packages\selenium\webdriver\remote\webdriver.py", line 321, in execute
    self.error_handler.check_response(response)
  File "c:\users\kai\pycharmprojects\pythonproject\venv\lib\site-packages\selenium\webdriver\remote\errorhandler.py", line 242, in check_response
    raise exception_class(message, screen, stacktrace)
selenium.common.exceptions.NoSuchElementException: Message: no such element: Unable to locate element: {"method":"xpath","selector":"//div[@id='income-statement']//div[contains(@class,'header-text')]//div[contains(@class,'options')]/div[1]/div"}
  (Session info: chrome=91.0.4472.124)

2021-07-15 16:59_080520_오디텍
Traceback (most recent call last):
  File "C:\Users\kai\PycharmProjects\pythonProject\noname\noname\spiders\noname_spider.py", line 250, in company_scrapy
    button = self.driver.find_element_by_xpath(
  File "c:\users\kai\pycharmprojects\pythonproject\venv\lib\site-packages\selenium\webdriver\remote\webdriver.py", line 394, in find_element_by_xpath
    return self.find_element(by=By.XPATH, value=xpath)
  File "c:\users\kai\pycharmprojects\pythonproject\venv\lib\site-packages\selenium\webdriver\remote\webdriver.py", line 976, in find_element
    return self.execute(Command.FIND_ELEMENT, {
  File "c:\users\kai\pycharmprojects\pythonproject\venv\lib\site-packages\selenium\webdriver\remote\webdriver.py", line 321, in execute
    self.error_handler.check_response(response)
  File "c:\users\kai\pycharmprojects\pythonproject\venv\lib\site-packages\selenium\webdriver\remote\errorhandler.py", line 242, in check_response
    raise exception_class(message, screen, stacktrace)
selenium.common.exceptions.NoSuchElementException: Message: no such element: Unable to locate element: {"method":"xpath","selector":"//div[@id='income-statement']//div[contains(@class,'header-text')]//div[contains(@class,'options')]/div[1]/div"}
  (Session info: chrome=91.0.4472.124)

2021-07-15 17:01_080520_오디텍
Traceback (most recent call last):
  File "C:\Users\kai\PycharmProjects\pythonProject\noname\noname\spiders\noname_spider.py", line 283, in company_scrapy
    button = self.driver.find_element_by_xpath(
  File "c:\users\kai\pycharmprojects\pythonproject\venv\lib\site-packages\selenium\webdriver\remote\webdriver.py", line 394, in find_element_by_xpath
    return self.find_element(by=By.XPATH, value=xpath)
  File "c:\users\kai\pycharmprojects\pythonproject\venv\lib\site-packages\selenium\webdriver\remote\webdriver.py", line 976, in find_element
    return self.execute(Command.FIND_ELEMENT, {
  File "c:\users\kai\pycharmprojects\pythonproject\venv\lib\site-packages\selenium\webdriver\remote\webdriver.py", line 321, in execute
    self.error_handler.check_response(response)
  File "c:\users\kai\pycharmprojects\pythonproject\venv\lib\site-packages\selenium\webdriver\remote\errorhandler.py", line 242, in check_response
    raise exception_class(message, screen, stacktrace)
selenium.common.exceptions.NoSuchElementException: Message: no such element: Unable to locate element: {"method":"xpath","selector":"//div[@id='income-statement']//div[contains(@class,'table-container')]//span[@class='table-export-button']"}
  (Session info: chrome=91.0.4472.124)

2021-07-15 17:06_080010_이상네트웍스
Traceback (most recent call last):
  File "c:\users\kai\pycharmprojects\pythonproject\venv\lib\site-packages\urllib3\connection.py", line 169, in _new_conn
    conn = connection.create_connection(
  File "c:\users\kai\pycharmprojects\pythonproject\venv\lib\site-packages\urllib3\util\connection.py", line 96, in create_connection
    raise err
  File "c:\users\kai\pycharmprojects\pythonproject\venv\lib\site-packages\urllib3\util\connection.py", line 86, in create_connection
    sock.connect(sa)
ConnectionRefusedError: [WinError 10061] 대상 컴퓨터에서 연결을 거부했으므로 연결하지 못했습니다

During handling of the above exception, another exception occurred:

Traceback (most recent call last):
  File "c:\users\kai\pycharmprojects\pythonproject\venv\lib\site-packages\urllib3\connectionpool.py", line 699, in urlopen
    httplib_response = self._make_request(
  File "c:\users\kai\pycharmprojects\pythonproject\venv\lib\site-packages\urllib3\connectionpool.py", line 394, in _make_request
    conn.request(method, url, **httplib_request_kw)
  File "c:\users\kai\pycharmprojects\pythonproject\venv\lib\site-packages\urllib3\connection.py", line 234, in request
    super(HTTPConnection, self).request(method, url, body=body, headers=headers)
  File "C:\Users\kai\AppData\Local\Programs\Python\Python39\lib\http\client.py", line 1253, in request
    self._send_request(method, url, body, headers, encode_chunked)
  File "C:\Users\kai\AppData\Local\Programs\Python\Python39\lib\http\client.py", line 1299, in _send_request
    self.endheaders(body, encode_chunked=encode_chunked)
  File "C:\Users\kai\AppData\Local\Programs\Python\Python39\lib\http\client.py", line 1248, in endheaders
    self._send_output(message_body, encode_chunked=encode_chunked)
  File "C:\Users\kai\AppData\Local\Programs\Python\Python39\lib\http\client.py", line 1008, in _send_output
    self.send(msg)
  File "C:\Users\kai\AppData\Local\Programs\Python\Python39\lib\http\client.py", line 948, in send
    self.connect()
  File "c:\users\kai\pycharmprojects\pythonproject\venv\lib\site-packages\urllib3\connection.py", line 200, in connect
    conn = self._new_conn()
  File "c:\users\kai\pycharmprojects\pythonproject\venv\lib\site-packages\urllib3\connection.py", line 181, in _new_conn
    raise NewConnectionError(
urllib3.exceptions.NewConnectionError: <urllib3.connection.HTTPConnection object at 0x00000271E51BA790>: Failed to establish a new connection: [WinError 10061] 대상 컴퓨터에서 연결을 거부했으므로 연결하지 못했습니다

During handling of the above exception, another exception occurred:

Traceback (most recent call last):
  File "C:\Users\kai\PycharmProjects\pythonProject\noname\noname\spiders\noname_spider.py", line 141, in company_scrapy
    search_bar.send_keys(company["단축코드"])
  File "c:\users\kai\pycharmprojects\pythonproject\venv\lib\site-packages\selenium\webdriver\remote\webelement.py", line 477, in send_keys
    self._execute(Command.SEND_KEYS_TO_ELEMENT,
  File "c:\users\kai\pycharmprojects\pythonproject\venv\lib\site-packages\selenium\webdriver\remote\webelement.py", line 633, in _execute
    return self._parent.execute(command, params)
  File "c:\users\kai\pycharmprojects\pythonproject\venv\lib\site-packages\selenium\webdriver\remote\webdriver.py", line 319, in execute
    response = self.command_executor.execute(driver_command, params)
  File "c:\users\kai\pycharmprojects\pythonproject\venv\lib\site-packages\selenium\webdriver\remote\remote_connection.py", line 374, in execute
    return self._request(command_info[0], url, body=data)
  File "c:\users\kai\pycharmprojects\pythonproject\venv\lib\site-packages\selenium\webdriver\remote\remote_connection.py", line 397, in _request
    resp = self._conn.request(method, url, body=body, headers=headers)
  File "c:\users\kai\pycharmprojects\pythonproject\venv\lib\site-packages\urllib3\request.py", line 78, in request
    return self.request_encode_body(
  File "c:\users\kai\pycharmprojects\pythonproject\venv\lib\site-packages\urllib3\request.py", line 170, in request_encode_body
    return self.urlopen(method, url, **extra_kw)
  File "c:\users\kai\pycharmprojects\pythonproject\venv\lib\site-packages\urllib3\poolmanager.py", line 375, in urlopen
    response = conn.urlopen(method, u.request_uri, **kw)
  File "c:\users\kai\pycharmprojects\pythonproject\venv\lib\site-packages\urllib3\connectionpool.py", line 783, in urlopen
    return self.urlopen(
  File "c:\users\kai\pycharmprojects\pythonproject\venv\lib\site-packages\urllib3\connectionpool.py", line 783, in urlopen
    return self.urlopen(
  File "c:\users\kai\pycharmprojects\pythonproject\venv\lib\site-packages\urllib3\connectionpool.py", line 783, in urlopen
    return self.urlopen(
  File "c:\users\kai\pycharmprojects\pythonproject\venv\lib\site-packages\urllib3\connectionpool.py", line 755, in urlopen
    retries = retries.increment(
  File "c:\users\kai\pycharmprojects\pythonproject\venv\lib\site-packages\urllib3\util\retry.py", line 574, in increment
    raise MaxRetryError(_pool, url, error or ResponseError(cause))
urllib3.exceptions.MaxRetryError: HTTPConnectionPool(host='127.0.0.1', port=60099): Max retries exceeded with url: /session/1f456716b3fba9bb27952b33d3251caf/element/d166284b-cb5f-474c-925c-4494211957d5/value (Caused by NewConnectionError('<urllib3.connection.HTTPConnection object at 0x00000271E51BA790>: Failed to establish a new connection: [WinError 10061] 대상 컴퓨터에서 연결을 거부했으므로 연결하지 못했습니다'))
2021-07-15 17:06_080010_이상네트웍스
Traceback (most recent call last):
  File "c:\users\kai\pycharmprojects\pythonproject\venv\lib\site-packages\urllib3\connection.py", line 169, in _new_conn
    conn = connection.create_connection(
  File "c:\users\kai\pycharmprojects\pythonproject\venv\lib\site-packages\urllib3\util\connection.py", line 96, in create_connection
    raise err
  File "c:\users\kai\pycharmprojects\pythonproject\venv\lib\site-packages\urllib3\util\connection.py", line 86, in create_connection
    sock.connect(sa)
ConnectionRefusedError: [WinError 10061] 대상 컴퓨터에서 연결을 거부했으므로 연결하지 못했습니다

During handling of the above exception, another exception occurred:

Traceback (most recent call last):
  File "c:\users\kai\pycharmprojects\pythonproject\venv\lib\site-packages\urllib3\connectionpool.py", line 699, in urlopen
    httplib_response = self._make_request(
  File "c:\users\kai\pycharmprojects\pythonproject\venv\lib\site-packages\urllib3\connectionpool.py", line 394, in _make_request
    conn.request(method, url, **httplib_request_kw)
  File "c:\users\kai\pycharmprojects\pythonproject\venv\lib\site-packages\urllib3\connection.py", line 234, in request
    super(HTTPConnection, self).request(method, url, body=body, headers=headers)
  File "C:\Users\kai\AppData\Local\Programs\Python\Python39\lib\http\client.py", line 1253, in request
    self._send_request(method, url, body, headers, encode_chunked)
  File "C:\Users\kai\AppData\Local\Programs\Python\Python39\lib\http\client.py", line 1299, in _send_request
    self.endheaders(body, encode_chunked=encode_chunked)
  File "C:\Users\kai\AppData\Local\Programs\Python\Python39\lib\http\client.py", line 1248, in endheaders
    self._send_output(message_body, encode_chunked=encode_chunked)
  File "C:\Users\kai\AppData\Local\Programs\Python\Python39\lib\http\client.py", line 1008, in _send_output
    self.send(msg)
  File "C:\Users\kai\AppData\Local\Programs\Python\Python39\lib\http\client.py", line 948, in send
    self.connect()
  File "c:\users\kai\pycharmprojects\pythonproject\venv\lib\site-packages\urllib3\connection.py", line 200, in connect
    conn = self._new_conn()
  File "c:\users\kai\pycharmprojects\pythonproject\venv\lib\site-packages\urllib3\connection.py", line 181, in _new_conn
    raise NewConnectionError(
urllib3.exceptions.NewConnectionError: <urllib3.connection.HTTPConnection object at 0x00000271E513AEB0>: Failed to establish a new connection: [WinError 10061] 대상 컴퓨터에서 연결을 거부했으므로 연결하지 못했습니다

During handling of the above exception, another exception occurred:

Traceback (most recent call last):
  File "C:\Users\kai\PycharmProjects\pythonProject\noname\noname\spiders\noname_spider.py", line 127, in company_scrapy
    menu1_button = self.driver.find_element_by_xpath(
  File "c:\users\kai\pycharmprojects\pythonproject\venv\lib\site-packages\selenium\webdriver\remote\webdriver.py", line 394, in find_element_by_xpath
    return self.find_element(by=By.XPATH, value=xpath)
  File "c:\users\kai\pycharmprojects\pythonproject\venv\lib\site-packages\selenium\webdriver\remote\webdriver.py", line 976, in find_element
    return self.execute(Command.FIND_ELEMENT, {
  File "c:\users\kai\pycharmprojects\pythonproject\venv\lib\site-packages\selenium\webdriver\remote\webdriver.py", line 319, in execute
    response = self.command_executor.execute(driver_command, params)
  File "c:\users\kai\pycharmprojects\pythonproject\venv\lib\site-packages\selenium\webdriver\remote\remote_connection.py", line 374, in execute
    return self._request(command_info[0], url, body=data)
  File "c:\users\kai\pycharmprojects\pythonproject\venv\lib\site-packages\selenium\webdriver\remote\remote_connection.py", line 397, in _request
    resp = self._conn.request(method, url, body=body, headers=headers)
  File "c:\users\kai\pycharmprojects\pythonproject\venv\lib\site-packages\urllib3\request.py", line 78, in request
    return self.request_encode_body(
  File "c:\users\kai\pycharmprojects\pythonproject\venv\lib\site-packages\urllib3\request.py", line 170, in request_encode_body
    return self.urlopen(method, url, **extra_kw)
  File "c:\users\kai\pycharmprojects\pythonproject\venv\lib\site-packages\urllib3\poolmanager.py", line 375, in urlopen
    response = conn.urlopen(method, u.request_uri, **kw)
  File "c:\users\kai\pycharmprojects\pythonproject\venv\lib\site-packages\urllib3\connectionpool.py", line 783, in urlopen
    return self.urlopen(
  File "c:\users\kai\pycharmprojects\pythonproject\venv\lib\site-packages\urllib3\connectionpool.py", line 783, in urlopen
    return self.urlopen(
  File "c:\users\kai\pycharmprojects\pythonproject\venv\lib\site-packages\urllib3\connectionpool.py", line 783, in urlopen
    return self.urlopen(
  File "c:\users\kai\pycharmprojects\pythonproject\venv\lib\site-packages\urllib3\connectionpool.py", line 755, in urlopen
    retries = retries.increment(
  File "c:\users\kai\pycharmprojects\pythonproject\venv\lib\site-packages\urllib3\util\retry.py", line 574, in increment
    raise MaxRetryError(_pool, url, error or ResponseError(cause))
urllib3.exceptions.MaxRetryError: HTTPConnectionPool(host='127.0.0.1', port=60099): Max retries exceeded with url: /session/1f456716b3fba9bb27952b33d3251caf/element (Caused by NewConnectionError('<urllib3.connection.HTTPConnection object at 0x00000271E513AEB0>: Failed to establish a new connection: [WinError 10061] 대상 컴퓨터에서 연결을 거부했으므로 연결하지 못했습니다'))
2021-07-15 17:06_080010_이상네트웍스
Traceback (most recent call last):
  File "c:\users\kai\pycharmprojects\pythonproject\venv\lib\site-packages\urllib3\connection.py", line 169, in _new_conn
    conn = connection.create_connection(
  File "c:\users\kai\pycharmprojects\pythonproject\venv\lib\site-packages\urllib3\util\connection.py", line 96, in create_connection
    raise err
  File "c:\users\kai\pycharmprojects\pythonproject\venv\lib\site-packages\urllib3\util\connection.py", line 86, in create_connection
    sock.connect(sa)
ConnectionRefusedError: [WinError 10061] 대상 컴퓨터에서 연결을 거부했으므로 연결하지 못했습니다

During handling of the above exception, another exception occurred:

Traceback (most recent call last):
  File "c:\users\kai\pycharmprojects\pythonproject\venv\lib\site-packages\urllib3\connectionpool.py", line 699, in urlopen
    httplib_response = self._make_request(
  File "c:\users\kai\pycharmprojects\pythonproject\venv\lib\site-packages\urllib3\connectionpool.py", line 394, in _make_request
    conn.request(method, url, **httplib_request_kw)
  File "c:\users\kai\pycharmprojects\pythonproject\venv\lib\site-packages\urllib3\connection.py", line 234, in request
    super(HTTPConnection, self).request(method, url, body=body, headers=headers)
  File "C:\Users\kai\AppData\Local\Programs\Python\Python39\lib\http\client.py", line 1253, in request
    self._send_request(method, url, body, headers, encode_chunked)
  File "C:\Users\kai\AppData\Local\Programs\Python\Python39\lib\http\client.py", line 1299, in _send_request
    self.endheaders(body, encode_chunked=encode_chunked)
  File "C:\Users\kai\AppData\Local\Programs\Python\Python39\lib\http\client.py", line 1248, in endheaders
    self._send_output(message_body, encode_chunked=encode_chunked)
  File "C:\Users\kai\AppData\Local\Programs\Python\Python39\lib\http\client.py", line 1008, in _send_output
    self.send(msg)
  File "C:\Users\kai\AppData\Local\Programs\Python\Python39\lib\http\client.py", line 948, in send
    self.connect()
  File "c:\users\kai\pycharmprojects\pythonproject\venv\lib\site-packages\urllib3\connection.py", line 200, in connect
    conn = self._new_conn()
  File "c:\users\kai\pycharmprojects\pythonproject\venv\lib\site-packages\urllib3\connection.py", line 181, in _new_conn
    raise NewConnectionError(
urllib3.exceptions.NewConnectionError: <urllib3.connection.HTTPConnection object at 0x00000271E51DFD30>: Failed to establish a new connection: [WinError 10061] 대상 컴퓨터에서 연결을 거부했으므로 연결하지 못했습니다

During handling of the above exception, another exception occurred:

Traceback (most recent call last):
  File "C:\Users\kai\PycharmProjects\pythonProject\noname\noname\spiders\noname_spider.py", line 127, in company_scrapy
    menu1_button = self.driver.find_element_by_xpath(
  File "c:\users\kai\pycharmprojects\pythonproject\venv\lib\site-packages\selenium\webdriver\remote\webdriver.py", line 394, in find_element_by_xpath
    return self.find_element(by=By.XPATH, value=xpath)
  File "c:\users\kai\pycharmprojects\pythonproject\venv\lib\site-packages\selenium\webdriver\remote\webdriver.py", line 976, in find_element
    return self.execute(Command.FIND_ELEMENT, {
  File "c:\users\kai\pycharmprojects\pythonproject\venv\lib\site-packages\selenium\webdriver\remote\webdriver.py", line 319, in execute
    response = self.command_executor.execute(driver_command, params)
  File "c:\users\kai\pycharmprojects\pythonproject\venv\lib\site-packages\selenium\webdriver\remote\remote_connection.py", line 374, in execute
    return self._request(command_info[0], url, body=data)
  File "c:\users\kai\pycharmprojects\pythonproject\venv\lib\site-packages\selenium\webdriver\remote\remote_connection.py", line 397, in _request
    resp = self._conn.request(method, url, body=body, headers=headers)
  File "c:\users\kai\pycharmprojects\pythonproject\venv\lib\site-packages\urllib3\request.py", line 78, in request
    return self.request_encode_body(
  File "c:\users\kai\pycharmprojects\pythonproject\venv\lib\site-packages\urllib3\request.py", line 170, in request_encode_body
    return self.urlopen(method, url, **extra_kw)
  File "c:\users\kai\pycharmprojects\pythonproject\venv\lib\site-packages\urllib3\poolmanager.py", line 375, in urlopen
    response = conn.urlopen(method, u.request_uri, **kw)
  File "c:\users\kai\pycharmprojects\pythonproject\venv\lib\site-packages\urllib3\connectionpool.py", line 783, in urlopen
    return self.urlopen(
  File "c:\users\kai\pycharmprojects\pythonproject\venv\lib\site-packages\urllib3\connectionpool.py", line 783, in urlopen
    return self.urlopen(
  File "c:\users\kai\pycharmprojects\pythonproject\venv\lib\site-packages\urllib3\connectionpool.py", line 783, in urlopen
    return self.urlopen(
  File "c:\users\kai\pycharmprojects\pythonproject\venv\lib\site-packages\urllib3\connectionpool.py", line 755, in urlopen
    retries = retries.increment(
  File "c:\users\kai\pycharmprojects\pythonproject\venv\lib\site-packages\urllib3\util\retry.py", line 574, in increment
    raise MaxRetryError(_pool, url, error or ResponseError(cause))
urllib3.exceptions.MaxRetryError: HTTPConnectionPool(host='127.0.0.1', port=60099): Max retries exceeded with url: /session/1f456716b3fba9bb27952b33d3251caf/element (Caused by NewConnectionError('<urllib3.connection.HTTPConnection object at 0x00000271E51DFD30>: Failed to establish a new connection: [WinError 10061] 대상 컴퓨터에서 연결을 거부했으므로 연결하지 못했습니다'))
2021-07-15 17:06_080160_모두투어
Traceback (most recent call last):
  File "c:\users\kai\pycharmprojects\pythonproject\venv\lib\site-packages\urllib3\connection.py", line 169, in _new_conn
    conn = connection.create_connection(
  File "c:\users\kai\pycharmprojects\pythonproject\venv\lib\site-packages\urllib3\util\connection.py", line 96, in create_connection
    raise err
  File "c:\users\kai\pycharmprojects\pythonproject\venv\lib\site-packages\urllib3\util\connection.py", line 86, in create_connection
    sock.connect(sa)
ConnectionRefusedError: [WinError 10061] 대상 컴퓨터에서 연결을 거부했으므로 연결하지 못했습니다

During handling of the above exception, another exception occurred:

Traceback (most recent call last):
  File "c:\users\kai\pycharmprojects\pythonproject\venv\lib\site-packages\urllib3\connectionpool.py", line 699, in urlopen
    httplib_response = self._make_request(
  File "c:\users\kai\pycharmprojects\pythonproject\venv\lib\site-packages\urllib3\connectionpool.py", line 394, in _make_request
    conn.request(method, url, **httplib_request_kw)
  File "c:\users\kai\pycharmprojects\pythonproject\venv\lib\site-packages\urllib3\connection.py", line 234, in request
    super(HTTPConnection, self).request(method, url, body=body, headers=headers)
  File "C:\Users\kai\AppData\Local\Programs\Python\Python39\lib\http\client.py", line 1253, in request
    self._send_request(method, url, body, headers, encode_chunked)
  File "C:\Users\kai\AppData\Local\Programs\Python\Python39\lib\http\client.py", line 1299, in _send_request
    self.endheaders(body, encode_chunked=encode_chunked)
  File "C:\Users\kai\AppData\Local\Programs\Python\Python39\lib\http\client.py", line 1248, in endheaders
    self._send_output(message_body, encode_chunked=encode_chunked)
  File "C:\Users\kai\AppData\Local\Programs\Python\Python39\lib\http\client.py", line 1008, in _send_output
    self.send(msg)
  File "C:\Users\kai\AppData\Local\Programs\Python\Python39\lib\http\client.py", line 948, in send
    self.connect()
  File "c:\users\kai\pycharmprojects\pythonproject\venv\lib\site-packages\urllib3\connection.py", line 200, in connect
    conn = self._new_conn()
  File "c:\users\kai\pycharmprojects\pythonproject\venv\lib\site-packages\urllib3\connection.py", line 181, in _new_conn
    raise NewConnectionError(
urllib3.exceptions.NewConnectionError: <urllib3.connection.HTTPConnection object at 0x00000271E52BF2B0>: Failed to establish a new connection: [WinError 10061] 대상 컴퓨터에서 연결을 거부했으므로 연결하지 못했습니다

During handling of the above exception, another exception occurred:

Traceback (most recent call last):
  File "C:\Users\kai\PycharmProjects\pythonProject\noname\noname\spiders\noname_spider.py", line 127, in company_scrapy
    menu1_button = self.driver.find_element_by_xpath(
  File "c:\users\kai\pycharmprojects\pythonproject\venv\lib\site-packages\selenium\webdriver\remote\webdriver.py", line 394, in find_element_by_xpath
    return self.find_element(by=By.XPATH, value=xpath)
  File "c:\users\kai\pycharmprojects\pythonproject\venv\lib\site-packages\selenium\webdriver\remote\webdriver.py", line 976, in find_element
    return self.execute(Command.FIND_ELEMENT, {
  File "c:\users\kai\pycharmprojects\pythonproject\venv\lib\site-packages\selenium\webdriver\remote\webdriver.py", line 319, in execute
    response = self.command_executor.execute(driver_command, params)
  File "c:\users\kai\pycharmprojects\pythonproject\venv\lib\site-packages\selenium\webdriver\remote\remote_connection.py", line 374, in execute
    return self._request(command_info[0], url, body=data)
  File "c:\users\kai\pycharmprojects\pythonproject\venv\lib\site-packages\selenium\webdriver\remote\remote_connection.py", line 397, in _request
    resp = self._conn.request(method, url, body=body, headers=headers)
  File "c:\users\kai\pycharmprojects\pythonproject\venv\lib\site-packages\urllib3\request.py", line 78, in request
    return self.request_encode_body(
  File "c:\users\kai\pycharmprojects\pythonproject\venv\lib\site-packages\urllib3\request.py", line 170, in request_encode_body
    return self.urlopen(method, url, **extra_kw)
  File "c:\users\kai\pycharmprojects\pythonproject\venv\lib\site-packages\urllib3\poolmanager.py", line 375, in urlopen
    response = conn.urlopen(method, u.request_uri, **kw)
  File "c:\users\kai\pycharmprojects\pythonproject\venv\lib\site-packages\urllib3\connectionpool.py", line 783, in urlopen
    return self.urlopen(
  File "c:\users\kai\pycharmprojects\pythonproject\venv\lib\site-packages\urllib3\connectionpool.py", line 783, in urlopen
    return self.urlopen(
  File "c:\users\kai\pycharmprojects\pythonproject\venv\lib\site-packages\urllib3\connectionpool.py", line 783, in urlopen
    return self.urlopen(
  File "c:\users\kai\pycharmprojects\pythonproject\venv\lib\site-packages\urllib3\connectionpool.py", line 755, in urlopen
    retries = retries.increment(
  File "c:\users\kai\pycharmprojects\pythonproject\venv\lib\site-packages\urllib3\util\retry.py", line 574, in increment
    raise MaxRetryError(_pool, url, error or ResponseError(cause))
urllib3.exceptions.MaxRetryError: HTTPConnectionPool(host='127.0.0.1', port=60099): Max retries exceeded with url: /session/1f456716b3fba9bb27952b33d3251caf/element (Caused by NewConnectionError('<urllib3.connection.HTTPConnection object at 0x00000271E52BF2B0>: Failed to establish a new connection: [WinError 10061] 대상 컴퓨터에서 연결을 거부했으므로 연결하지 못했습니다'))
2021-07-15 17:06_080160_모두투어
Traceback (most recent call last):
  File "c:\users\kai\pycharmprojects\pythonproject\venv\lib\site-packages\urllib3\connection.py", line 169, in _new_conn
    conn = connection.create_connection(
  File "c:\users\kai\pycharmprojects\pythonproject\venv\lib\site-packages\urllib3\util\connection.py", line 96, in create_connection
    raise err
  File "c:\users\kai\pycharmprojects\pythonproject\venv\lib\site-packages\urllib3\util\connection.py", line 86, in create_connection
    sock.connect(sa)
ConnectionRefusedError: [WinError 10061] 대상 컴퓨터에서 연결을 거부했으므로 연결하지 못했습니다

During handling of the above exception, another exception occurred:

Traceback (most recent call last):
  File "c:\users\kai\pycharmprojects\pythonproject\venv\lib\site-packages\urllib3\connectionpool.py", line 699, in urlopen
    httplib_response = self._make_request(
  File "c:\users\kai\pycharmprojects\pythonproject\venv\lib\site-packages\urllib3\connectionpool.py", line 394, in _make_request
    conn.request(method, url, **httplib_request_kw)
  File "c:\users\kai\pycharmprojects\pythonproject\venv\lib\site-packages\urllib3\connection.py", line 234, in request
    super(HTTPConnection, self).request(method, url, body=body, headers=headers)
  File "C:\Users\kai\AppData\Local\Programs\Python\Python39\lib\http\client.py", line 1253, in request
    self._send_request(method, url, body, headers, encode_chunked)
  File "C:\Users\kai\AppData\Local\Programs\Python\Python39\lib\http\client.py", line 1299, in _send_request
    self.endheaders(body, encode_chunked=encode_chunked)
  File "C:\Users\kai\AppData\Local\Programs\Python\Python39\lib\http\client.py", line 1248, in endheaders
    self._send_output(message_body, encode_chunked=encode_chunked)
  File "C:\Users\kai\AppData\Local\Programs\Python\Python39\lib\http\client.py", line 1008, in _send_output
    self.send(msg)
  File "C:\Users\kai\AppData\Local\Programs\Python\Python39\lib\http\client.py", line 948, in send
    self.connect()
  File "c:\users\kai\pycharmprojects\pythonproject\venv\lib\site-packages\urllib3\connection.py", line 200, in connect
    conn = self._new_conn()
  File "c:\users\kai\pycharmprojects\pythonproject\venv\lib\site-packages\urllib3\connection.py", line 181, in _new_conn
    raise NewConnectionError(
urllib3.exceptions.NewConnectionError: <urllib3.connection.HTTPConnection object at 0x00000271E51DFB80>: Failed to establish a new connection: [WinError 10061] 대상 컴퓨터에서 연결을 거부했으므로 연결하지 못했습니다

During handling of the above exception, another exception occurred:

Traceback (most recent call last):
  File "C:\Users\kai\PycharmProjects\pythonProject\noname\noname\spiders\noname_spider.py", line 127, in company_scrapy
    menu1_button = self.driver.find_element_by_xpath(
  File "c:\users\kai\pycharmprojects\pythonproject\venv\lib\site-packages\selenium\webdriver\remote\webdriver.py", line 394, in find_element_by_xpath
    return self.find_element(by=By.XPATH, value=xpath)
  File "c:\users\kai\pycharmprojects\pythonproject\venv\lib\site-packages\selenium\webdriver\remote\webdriver.py", line 976, in find_element
    return self.execute(Command.FIND_ELEMENT, {
  File "c:\users\kai\pycharmprojects\pythonproject\venv\lib\site-packages\selenium\webdriver\remote\webdriver.py", line 319, in execute
    response = self.command_executor.execute(driver_command, params)
  File "c:\users\kai\pycharmprojects\pythonproject\venv\lib\site-packages\selenium\webdriver\remote\remote_connection.py", line 374, in execute
    return self._request(command_info[0], url, body=data)
  File "c:\users\kai\pycharmprojects\pythonproject\venv\lib\site-packages\selenium\webdriver\remote\remote_connection.py", line 397, in _request
    resp = self._conn.request(method, url, body=body, headers=headers)
  File "c:\users\kai\pycharmprojects\pythonproject\venv\lib\site-packages\urllib3\request.py", line 78, in request
    return self.request_encode_body(
  File "c:\users\kai\pycharmprojects\pythonproject\venv\lib\site-packages\urllib3\request.py", line 170, in request_encode_body
    return self.urlopen(method, url, **extra_kw)
  File "c:\users\kai\pycharmprojects\pythonproject\venv\lib\site-packages\urllib3\poolmanager.py", line 375, in urlopen
    response = conn.urlopen(method, u.request_uri, **kw)
  File "c:\users\kai\pycharmprojects\pythonproject\venv\lib\site-packages\urllib3\connectionpool.py", line 783, in urlopen
    return self.urlopen(
  File "c:\users\kai\pycharmprojects\pythonproject\venv\lib\site-packages\urllib3\connectionpool.py", line 783, in urlopen
    return self.urlopen(
  File "c:\users\kai\pycharmprojects\pythonproject\venv\lib\site-packages\urllib3\connectionpool.py", line 783, in urlopen
    return self.urlopen(
  File "c:\users\kai\pycharmprojects\pythonproject\venv\lib\site-packages\urllib3\connectionpool.py", line 755, in urlopen
    retries = retries.increment(
  File "c:\users\kai\pycharmprojects\pythonproject\venv\lib\site-packages\urllib3\util\retry.py", line 574, in increment
    raise MaxRetryError(_pool, url, error or ResponseError(cause))
urllib3.exceptions.MaxRetryError: HTTPConnectionPool(host='127.0.0.1', port=60099): Max retries exceeded with url: /session/1f456716b3fba9bb27952b33d3251caf/element (Caused by NewConnectionError('<urllib3.connection.HTTPConnection object at 0x00000271E51DFB80>: Failed to establish a new connection: [WinError 10061] 대상 컴퓨터에서 연결을 거부했으므로 연결하지 못했습니다'))
2021-07-15 17:06_080160_모두투어
Traceback (most recent call last):
  File "c:\users\kai\pycharmprojects\pythonproject\venv\lib\site-packages\urllib3\connection.py", line 169, in _new_conn
    conn = connection.create_connection(
  File "c:\users\kai\pycharmprojects\pythonproject\venv\lib\site-packages\urllib3\util\connection.py", line 96, in create_connection
    raise err
  File "c:\users\kai\pycharmprojects\pythonproject\venv\lib\site-packages\urllib3\util\connection.py", line 86, in create_connection
    sock.connect(sa)
ConnectionRefusedError: [WinError 10061] 대상 컴퓨터에서 연결을 거부했으므로 연결하지 못했습니다

During handling of the above exception, another exception occurred:

Traceback (most recent call last):
  File "c:\users\kai\pycharmprojects\pythonproject\venv\lib\site-packages\urllib3\connectionpool.py", line 699, in urlopen
    httplib_response = self._make_request(
  File "c:\users\kai\pycharmprojects\pythonproject\venv\lib\site-packages\urllib3\connectionpool.py", line 394, in _make_request
    conn.request(method, url, **httplib_request_kw)
  File "c:\users\kai\pycharmprojects\pythonproject\venv\lib\site-packages\urllib3\connection.py", line 234, in request
    super(HTTPConnection, self).request(method, url, body=body, headers=headers)
  File "C:\Users\kai\AppData\Local\Programs\Python\Python39\lib\http\client.py", line 1253, in request
    self._send_request(method, url, body, headers, encode_chunked)
  File "C:\Users\kai\AppData\Local\Programs\Python\Python39\lib\http\client.py", line 1299, in _send_request
    self.endheaders(body, encode_chunked=encode_chunked)
  File "C:\Users\kai\AppData\Local\Programs\Python\Python39\lib\http\client.py", line 1248, in endheaders
    self._send_output(message_body, encode_chunked=encode_chunked)
  File "C:\Users\kai\AppData\Local\Programs\Python\Python39\lib\http\client.py", line 1008, in _send_output
    self.send(msg)
  File "C:\Users\kai\AppData\Local\Programs\Python\Python39\lib\http\client.py", line 948, in send
    self.connect()
  File "c:\users\kai\pycharmprojects\pythonproject\venv\lib\site-packages\urllib3\connection.py", line 200, in connect
    conn = self._new_conn()
  File "c:\users\kai\pycharmprojects\pythonproject\venv\lib\site-packages\urllib3\connection.py", line 181, in _new_conn
    raise NewConnectionError(
urllib3.exceptions.NewConnectionError: <urllib3.connection.HTTPConnection object at 0x00000271E51BAAC0>: Failed to establish a new connection: [WinError 10061] 대상 컴퓨터에서 연결을 거부했으므로 연결하지 못했습니다

During handling of the above exception, another exception occurred:

Traceback (most recent call last):
  File "C:\Users\kai\PycharmProjects\pythonProject\noname\noname\spiders\noname_spider.py", line 127, in company_scrapy
    menu1_button = self.driver.find_element_by_xpath(
  File "c:\users\kai\pycharmprojects\pythonproject\venv\lib\site-packages\selenium\webdriver\remote\webdriver.py", line 394, in find_element_by_xpath
    return self.find_element(by=By.XPATH, value=xpath)
  File "c:\users\kai\pycharmprojects\pythonproject\venv\lib\site-packages\selenium\webdriver\remote\webdriver.py", line 976, in find_element
    return self.execute(Command.FIND_ELEMENT, {
  File "c:\users\kai\pycharmprojects\pythonproject\venv\lib\site-packages\selenium\webdriver\remote\webdriver.py", line 319, in execute
    response = self.command_executor.execute(driver_command, params)
  File "c:\users\kai\pycharmprojects\pythonproject\venv\lib\site-packages\selenium\webdriver\remote\remote_connection.py", line 374, in execute
    return self._request(command_info[0], url, body=data)
  File "c:\users\kai\pycharmprojects\pythonproject\venv\lib\site-packages\selenium\webdriver\remote\remote_connection.py", line 397, in _request
    resp = self._conn.request(method, url, body=body, headers=headers)
  File "c:\users\kai\pycharmprojects\pythonproject\venv\lib\site-packages\urllib3\request.py", line 78, in request
    return self.request_encode_body(
  File "c:\users\kai\pycharmprojects\pythonproject\venv\lib\site-packages\urllib3\request.py", line 170, in request_encode_body
    return self.urlopen(method, url, **extra_kw)
  File "c:\users\kai\pycharmprojects\pythonproject\venv\lib\site-packages\urllib3\poolmanager.py", line 375, in urlopen
    response = conn.urlopen(method, u.request_uri, **kw)
  File "c:\users\kai\pycharmprojects\pythonproject\venv\lib\site-packages\urllib3\connectionpool.py", line 783, in urlopen
    return self.urlopen(
  File "c:\users\kai\pycharmprojects\pythonproject\venv\lib\site-packages\urllib3\connectionpool.py", line 783, in urlopen
    return self.urlopen(
  File "c:\users\kai\pycharmprojects\pythonproject\venv\lib\site-packages\urllib3\connectionpool.py", line 783, in urlopen
    return self.urlopen(
  File "c:\users\kai\pycharmprojects\pythonproject\venv\lib\site-packages\urllib3\connectionpool.py", line 755, in urlopen
    retries = retries.increment(
  File "c:\users\kai\pycharmprojects\pythonproject\venv\lib\site-packages\urllib3\util\retry.py", line 574, in increment
    raise MaxRetryError(_pool, url, error or ResponseError(cause))
urllib3.exceptions.MaxRetryError: HTTPConnectionPool(host='127.0.0.1', port=60099): Max retries exceeded with url: /session/1f456716b3fba9bb27952b33d3251caf/element (Caused by NewConnectionError('<urllib3.connection.HTTPConnection object at 0x00000271E51BAAC0>: Failed to establish a new connection: [WinError 10061] 대상 컴퓨터에서 연결을 거부했으므로 연결하지 못했습니다'))
2021-07-15 17:07_080220_제주반도체
Traceback (most recent call last):
  File "c:\users\kai\pycharmprojects\pythonproject\venv\lib\site-packages\urllib3\connection.py", line 169, in _new_conn
    conn = connection.create_connection(
  File "c:\users\kai\pycharmprojects\pythonproject\venv\lib\site-packages\urllib3\util\connection.py", line 96, in create_connection
    raise err
  File "c:\users\kai\pycharmprojects\pythonproject\venv\lib\site-packages\urllib3\util\connection.py", line 86, in create_connection
    sock.connect(sa)
ConnectionRefusedError: [WinError 10061] 대상 컴퓨터에서 연결을 거부했으므로 연결하지 못했습니다

During handling of the above exception, another exception occurred:

Traceback (most recent call last):
  File "c:\users\kai\pycharmprojects\pythonproject\venv\lib\site-packages\urllib3\connectionpool.py", line 699, in urlopen
    httplib_response = self._make_request(
  File "c:\users\kai\pycharmprojects\pythonproject\venv\lib\site-packages\urllib3\connectionpool.py", line 394, in _make_request
    conn.request(method, url, **httplib_request_kw)
  File "c:\users\kai\pycharmprojects\pythonproject\venv\lib\site-packages\urllib3\connection.py", line 234, in request
    super(HTTPConnection, self).request(method, url, body=body, headers=headers)
  File "C:\Users\kai\AppData\Local\Programs\Python\Python39\lib\http\client.py", line 1253, in request
    self._send_request(method, url, body, headers, encode_chunked)
  File "C:\Users\kai\AppData\Local\Programs\Python\Python39\lib\http\client.py", line 1299, in _send_request
    self.endheaders(body, encode_chunked=encode_chunked)
  File "C:\Users\kai\AppData\Local\Programs\Python\Python39\lib\http\client.py", line 1248, in endheaders
    self._send_output(message_body, encode_chunked=encode_chunked)
  File "C:\Users\kai\AppData\Local\Programs\Python\Python39\lib\http\client.py", line 1008, in _send_output
    self.send(msg)
  File "C:\Users\kai\AppData\Local\Programs\Python\Python39\lib\http\client.py", line 948, in send
    self.connect()
  File "c:\users\kai\pycharmprojects\pythonproject\venv\lib\site-packages\urllib3\connection.py", line 200, in connect
    conn = self._new_conn()
  File "c:\users\kai\pycharmprojects\pythonproject\venv\lib\site-packages\urllib3\connection.py", line 181, in _new_conn
    raise NewConnectionError(
urllib3.exceptions.NewConnectionError: <urllib3.connection.HTTPConnection object at 0x00000271E52BF580>: Failed to establish a new connection: [WinError 10061] 대상 컴퓨터에서 연결을 거부했으므로 연결하지 못했습니다

During handling of the above exception, another exception occurred:

Traceback (most recent call last):
  File "C:\Users\kai\PycharmProjects\pythonProject\noname\noname\spiders\noname_spider.py", line 127, in company_scrapy
    menu1_button = self.driver.find_element_by_xpath(
  File "c:\users\kai\pycharmprojects\pythonproject\venv\lib\site-packages\selenium\webdriver\remote\webdriver.py", line 394, in find_element_by_xpath
    return self.find_element(by=By.XPATH, value=xpath)
  File "c:\users\kai\pycharmprojects\pythonproject\venv\lib\site-packages\selenium\webdriver\remote\webdriver.py", line 976, in find_element
    return self.execute(Command.FIND_ELEMENT, {
  File "c:\users\kai\pycharmprojects\pythonproject\venv\lib\site-packages\selenium\webdriver\remote\webdriver.py", line 319, in execute
    response = self.command_executor.execute(driver_command, params)
  File "c:\users\kai\pycharmprojects\pythonproject\venv\lib\site-packages\selenium\webdriver\remote\remote_connection.py", line 374, in execute
    return self._request(command_info[0], url, body=data)
  File "c:\users\kai\pycharmprojects\pythonproject\venv\lib\site-packages\selenium\webdriver\remote\remote_connection.py", line 397, in _request
    resp = self._conn.request(method, url, body=body, headers=headers)
  File "c:\users\kai\pycharmprojects\pythonproject\venv\lib\site-packages\urllib3\request.py", line 78, in request
    return self.request_encode_body(
  File "c:\users\kai\pycharmprojects\pythonproject\venv\lib\site-packages\urllib3\request.py", line 170, in request_encode_body
    return self.urlopen(method, url, **extra_kw)
  File "c:\users\kai\pycharmprojects\pythonproject\venv\lib\site-packages\urllib3\poolmanager.py", line 375, in urlopen
    response = conn.urlopen(method, u.request_uri, **kw)
  File "c:\users\kai\pycharmprojects\pythonproject\venv\lib\site-packages\urllib3\connectionpool.py", line 783, in urlopen
    return self.urlopen(
  File "c:\users\kai\pycharmprojects\pythonproject\venv\lib\site-packages\urllib3\connectionpool.py", line 783, in urlopen
    return self.urlopen(
  File "c:\users\kai\pycharmprojects\pythonproject\venv\lib\site-packages\urllib3\connectionpool.py", line 783, in urlopen
    return self.urlopen(
  File "c:\users\kai\pycharmprojects\pythonproject\venv\lib\site-packages\urllib3\connectionpool.py", line 755, in urlopen
    retries = retries.increment(
  File "c:\users\kai\pycharmprojects\pythonproject\venv\lib\site-packages\urllib3\util\retry.py", line 574, in increment
    raise MaxRetryError(_pool, url, error or ResponseError(cause))
urllib3.exceptions.MaxRetryError: HTTPConnectionPool(host='127.0.0.1', port=60099): Max retries exceeded with url: /session/1f456716b3fba9bb27952b33d3251caf/element (Caused by NewConnectionError('<urllib3.connection.HTTPConnection object at 0x00000271E52BF580>: Failed to establish a new connection: [WinError 10061] 대상 컴퓨터에서 연결을 거부했으므로 연결하지 못했습니다'))
2021-07-15 17:07_080220_제주반도체
Traceback (most recent call last):
  File "c:\users\kai\pycharmprojects\pythonproject\venv\lib\site-packages\urllib3\connection.py", line 169, in _new_conn
    conn = connection.create_connection(
  File "c:\users\kai\pycharmprojects\pythonproject\venv\lib\site-packages\urllib3\util\connection.py", line 96, in create_connection
    raise err
  File "c:\users\kai\pycharmprojects\pythonproject\venv\lib\site-packages\urllib3\util\connection.py", line 86, in create_connection
    sock.connect(sa)
ConnectionRefusedError: [WinError 10061] 대상 컴퓨터에서 연결을 거부했으므로 연결하지 못했습니다

During handling of the above exception, another exception occurred:

Traceback (most recent call last):
  File "c:\users\kai\pycharmprojects\pythonproject\venv\lib\site-packages\urllib3\connectionpool.py", line 699, in urlopen
    httplib_response = self._make_request(
  File "c:\users\kai\pycharmprojects\pythonproject\venv\lib\site-packages\urllib3\connectionpool.py", line 394, in _make_request
    conn.request(method, url, **httplib_request_kw)
  File "c:\users\kai\pycharmprojects\pythonproject\venv\lib\site-packages\urllib3\connection.py", line 234, in request
    super(HTTPConnection, self).request(method, url, body=body, headers=headers)
  File "C:\Users\kai\AppData\Local\Programs\Python\Python39\lib\http\client.py", line 1253, in request
    self._send_request(method, url, body, headers, encode_chunked)
  File "C:\Users\kai\AppData\Local\Programs\Python\Python39\lib\http\client.py", line 1299, in _send_request
    self.endheaders(body, encode_chunked=encode_chunked)
  File "C:\Users\kai\AppData\Local\Programs\Python\Python39\lib\http\client.py", line 1248, in endheaders
    self._send_output(message_body, encode_chunked=encode_chunked)
  File "C:\Users\kai\AppData\Local\Programs\Python\Python39\lib\http\client.py", line 1008, in _send_output
    self.send(msg)
  File "C:\Users\kai\AppData\Local\Programs\Python\Python39\lib\http\client.py", line 948, in send
    self.connect()
  File "c:\users\kai\pycharmprojects\pythonproject\venv\lib\site-packages\urllib3\connection.py", line 200, in connect
    conn = self._new_conn()
  File "c:\users\kai\pycharmprojects\pythonproject\venv\lib\site-packages\urllib3\connection.py", line 181, in _new_conn
    raise NewConnectionError(
urllib3.exceptions.NewConnectionError: <urllib3.connection.HTTPConnection object at 0x00000271E52BFA90>: Failed to establish a new connection: [WinError 10061] 대상 컴퓨터에서 연결을 거부했으므로 연결하지 못했습니다

During handling of the above exception, another exception occurred:

Traceback (most recent call last):
  File "C:\Users\kai\PycharmProjects\pythonProject\noname\noname\spiders\noname_spider.py", line 127, in company_scrapy
    menu1_button = self.driver.find_element_by_xpath(
  File "c:\users\kai\pycharmprojects\pythonproject\venv\lib\site-packages\selenium\webdriver\remote\webdriver.py", line 394, in find_element_by_xpath
    return self.find_element(by=By.XPATH, value=xpath)
  File "c:\users\kai\pycharmprojects\pythonproject\venv\lib\site-packages\selenium\webdriver\remote\webdriver.py", line 976, in find_element
    return self.execute(Command.FIND_ELEMENT, {
  File "c:\users\kai\pycharmprojects\pythonproject\venv\lib\site-packages\selenium\webdriver\remote\webdriver.py", line 319, in execute
    response = self.command_executor.execute(driver_command, params)
  File "c:\users\kai\pycharmprojects\pythonproject\venv\lib\site-packages\selenium\webdriver\remote\remote_connection.py", line 374, in execute
    return self._request(command_info[0], url, body=data)
  File "c:\users\kai\pycharmprojects\pythonproject\venv\lib\site-packages\selenium\webdriver\remote\remote_connection.py", line 397, in _request
    resp = self._conn.request(method, url, body=body, headers=headers)
  File "c:\users\kai\pycharmprojects\pythonproject\venv\lib\site-packages\urllib3\request.py", line 78, in request
    return self.request_encode_body(
  File "c:\users\kai\pycharmprojects\pythonproject\venv\lib\site-packages\urllib3\request.py", line 170, in request_encode_body
    return self.urlopen(method, url, **extra_kw)
  File "c:\users\kai\pycharmprojects\pythonproject\venv\lib\site-packages\urllib3\poolmanager.py", line 375, in urlopen
    response = conn.urlopen(method, u.request_uri, **kw)
  File "c:\users\kai\pycharmprojects\pythonproject\venv\lib\site-packages\urllib3\connectionpool.py", line 783, in urlopen
    return self.urlopen(
  File "c:\users\kai\pycharmprojects\pythonproject\venv\lib\site-packages\urllib3\connectionpool.py", line 783, in urlopen
    return self.urlopen(
  File "c:\users\kai\pycharmprojects\pythonproject\venv\lib\site-packages\urllib3\connectionpool.py", line 783, in urlopen
    return self.urlopen(
  File "c:\users\kai\pycharmprojects\pythonproject\venv\lib\site-packages\urllib3\connectionpool.py", line 755, in urlopen
    retries = retries.increment(
  File "c:\users\kai\pycharmprojects\pythonproject\venv\lib\site-packages\urllib3\util\retry.py", line 574, in increment
    raise MaxRetryError(_pool, url, error or ResponseError(cause))
urllib3.exceptions.MaxRetryError: HTTPConnectionPool(host='127.0.0.1', port=60099): Max retries exceeded with url: /session/1f456716b3fba9bb27952b33d3251caf/element (Caused by NewConnectionError('<urllib3.connection.HTTPConnection object at 0x00000271E52BFA90>: Failed to establish a new connection: [WinError 10061] 대상 컴퓨터에서 연결을 거부했으므로 연결하지 못했습니다'))
2021-07-15 17:21_080720_한국유니온제약
Traceback (most recent call last):
  File "C:\Users\kai\PycharmProjects\pythonProject\noname\noname\spiders\noname_spider.py", line 274, in company_scrapy
    button = self.driver.find_element_by_xpath(
  File "c:\users\kai\pycharmprojects\pythonproject\venv\lib\site-packages\selenium\webdriver\remote\webdriver.py", line 394, in find_element_by_xpath
    return self.find_element(by=By.XPATH, value=xpath)
  File "c:\users\kai\pycharmprojects\pythonproject\venv\lib\site-packages\selenium\webdriver\remote\webdriver.py", line 976, in find_element
    return self.execute(Command.FIND_ELEMENT, {
  File "c:\users\kai\pycharmprojects\pythonproject\venv\lib\site-packages\selenium\webdriver\remote\webdriver.py", line 321, in execute
    self.error_handler.check_response(response)
  File "c:\users\kai\pycharmprojects\pythonproject\venv\lib\site-packages\selenium\webdriver\remote\errorhandler.py", line 242, in check_response
    raise exception_class(message, screen, stacktrace)
selenium.common.exceptions.NoSuchElementException: Message: no such element: Unable to locate element: {"method":"xpath","selector":"//div[@id='root']/div/div[contains(@class,'deepsesarch-dropdown-items')]/div[1]"}
  (Session info: chrome=91.0.4472.124)

2021-07-15 17:39_083500_에프엔에스테크
Traceback (most recent call last):
  File "C:\Users\kai\PycharmProjects\pythonProject\noname\noname\spiders\noname_spider.py", line 274, in company_scrapy
    button = self.driver.find_element_by_xpath(
  File "c:\users\kai\pycharmprojects\pythonproject\venv\lib\site-packages\selenium\webdriver\remote\webdriver.py", line 394, in find_element_by_xpath
    return self.find_element(by=By.XPATH, value=xpath)
  File "c:\users\kai\pycharmprojects\pythonproject\venv\lib\site-packages\selenium\webdriver\remote\webdriver.py", line 976, in find_element
    return self.execute(Command.FIND_ELEMENT, {
  File "c:\users\kai\pycharmprojects\pythonproject\venv\lib\site-packages\selenium\webdriver\remote\webdriver.py", line 321, in execute
    self.error_handler.check_response(response)
  File "c:\users\kai\pycharmprojects\pythonproject\venv\lib\site-packages\selenium\webdriver\remote\errorhandler.py", line 242, in check_response
    raise exception_class(message, screen, stacktrace)
selenium.common.exceptions.NoSuchElementException: Message: no such element: Unable to locate element: {"method":"xpath","selector":"//div[@id='root']/div/div[contains(@class,'deepsesarch-dropdown-items')]/div[1]"}
  (Session info: chrome=91.0.4472.124)

2021-07-15 17:54_084440_유비온
Traceback (most recent call last):
  File "C:\Users\kai\PycharmProjects\pythonProject\noname\noname\spiders\noname_spider.py", line 274, in company_scrapy
    button = self.driver.find_element_by_xpath(
  File "c:\users\kai\pycharmprojects\pythonproject\venv\lib\site-packages\selenium\webdriver\remote\webdriver.py", line 394, in find_element_by_xpath
    return self.find_element(by=By.XPATH, value=xpath)
  File "c:\users\kai\pycharmprojects\pythonproject\venv\lib\site-packages\selenium\webdriver\remote\webdriver.py", line 976, in find_element
    return self.execute(Command.FIND_ELEMENT, {
  File "c:\users\kai\pycharmprojects\pythonproject\venv\lib\site-packages\selenium\webdriver\remote\webdriver.py", line 321, in execute
    self.error_handler.check_response(response)
  File "c:\users\kai\pycharmprojects\pythonproject\venv\lib\site-packages\selenium\webdriver\remote\errorhandler.py", line 242, in check_response
    raise exception_class(message, screen, stacktrace)
selenium.common.exceptions.NoSuchElementException: Message: no such element: Unable to locate element: {"method":"xpath","selector":"//div[@id='root']/div/div[contains(@class,'deepsesarch-dropdown-items')]/div[1]"}
  (Session info: chrome=91.0.4472.124)

2021-07-15 17:57_084650_랩지노믹스
Traceback (most recent call last):
  File "C:\Users\kai\PycharmProjects\pythonProject\noname\noname\spiders\noname_spider.py", line 274, in company_scrapy
    button = self.driver.find_element_by_xpath(
  File "c:\users\kai\pycharmprojects\pythonproject\venv\lib\site-packages\selenium\webdriver\remote\webdriver.py", line 394, in find_element_by_xpath
    return self.find_element(by=By.XPATH, value=xpath)
  File "c:\users\kai\pycharmprojects\pythonproject\venv\lib\site-packages\selenium\webdriver\remote\webdriver.py", line 976, in find_element
    return self.execute(Command.FIND_ELEMENT, {
  File "c:\users\kai\pycharmprojects\pythonproject\venv\lib\site-packages\selenium\webdriver\remote\webdriver.py", line 321, in execute
    self.error_handler.check_response(response)
  File "c:\users\kai\pycharmprojects\pythonproject\venv\lib\site-packages\selenium\webdriver\remote\errorhandler.py", line 242, in check_response
    raise exception_class(message, screen, stacktrace)
selenium.common.exceptions.NoSuchElementException: Message: no such element: Unable to locate element: {"method":"xpath","selector":"//div[@id='root']/div/div[contains(@class,'deepsesarch-dropdown-items')]/div[1]"}
  (Session info: chrome=91.0.4472.124)

2021-07-15 18:02_084850_아이티엠반도체
Traceback (most recent call last):
  File "C:\Users\kai\PycharmProjects\pythonProject\noname\noname\spiders\noname_spider.py", line 274, in company_scrapy
    button = self.driver.find_element_by_xpath(
  File "c:\users\kai\pycharmprojects\pythonproject\venv\lib\site-packages\selenium\webdriver\remote\webdriver.py", line 394, in find_element_by_xpath
    return self.find_element(by=By.XPATH, value=xpath)
  File "c:\users\kai\pycharmprojects\pythonproject\venv\lib\site-packages\selenium\webdriver\remote\webdriver.py", line 976, in find_element
    return self.execute(Command.FIND_ELEMENT, {
  File "c:\users\kai\pycharmprojects\pythonproject\venv\lib\site-packages\selenium\webdriver\remote\webdriver.py", line 321, in execute
    self.error_handler.check_response(response)
  File "c:\users\kai\pycharmprojects\pythonproject\venv\lib\site-packages\selenium\webdriver\remote\errorhandler.py", line 242, in check_response
    raise exception_class(message, screen, stacktrace)
selenium.common.exceptions.NoSuchElementException: Message: no such element: Unable to locate element: {"method":"xpath","selector":"//div[@id='root']/div/div[contains(@class,'deepsesarch-dropdown-items')]/div[1]"}
  (Session info: chrome=91.0.4472.124)

2021-07-15 18:17_086220_네추럴FNP
Traceback (most recent call last):
  File "C:\Users\kai\PycharmProjects\pythonProject\noname\noname\spiders\noname_spider.py", line 274, in company_scrapy
    button = self.driver.find_element_by_xpath(
  File "c:\users\kai\pycharmprojects\pythonproject\venv\lib\site-packages\selenium\webdriver\remote\webdriver.py", line 394, in find_element_by_xpath
    return self.find_element(by=By.XPATH, value=xpath)
  File "c:\users\kai\pycharmprojects\pythonproject\venv\lib\site-packages\selenium\webdriver\remote\webdriver.py", line 976, in find_element
    return self.execute(Command.FIND_ELEMENT, {
  File "c:\users\kai\pycharmprojects\pythonproject\venv\lib\site-packages\selenium\webdriver\remote\webdriver.py", line 321, in execute
    self.error_handler.check_response(response)
  File "c:\users\kai\pycharmprojects\pythonproject\venv\lib\site-packages\selenium\webdriver\remote\errorhandler.py", line 242, in check_response
    raise exception_class(message, screen, stacktrace)
selenium.common.exceptions.NoSuchElementException: Message: no such element: Unable to locate element: {"method":"xpath","selector":"//div[@id='root']/div/div[contains(@class,'deepsesarch-dropdown-items')]/div[1]"}
  (Session info: chrome=91.0.4472.124)

2021-07-15 18:26_086520_에코프로
Traceback (most recent call last):
  File "C:\Users\kai\PycharmProjects\pythonProject\noname\noname\spiders\noname_spider.py", line 274, in company_scrapy
    button = self.driver.find_element_by_xpath(
  File "c:\users\kai\pycharmprojects\pythonproject\venv\lib\site-packages\selenium\webdriver\remote\webdriver.py", line 394, in find_element_by_xpath
    return self.find_element(by=By.XPATH, value=xpath)
  File "c:\users\kai\pycharmprojects\pythonproject\venv\lib\site-packages\selenium\webdriver\remote\webdriver.py", line 976, in find_element
    return self.execute(Command.FIND_ELEMENT, {
  File "c:\users\kai\pycharmprojects\pythonproject\venv\lib\site-packages\selenium\webdriver\remote\webdriver.py", line 321, in execute
    self.error_handler.check_response(response)
  File "c:\users\kai\pycharmprojects\pythonproject\venv\lib\site-packages\selenium\webdriver\remote\errorhandler.py", line 242, in check_response
    raise exception_class(message, screen, stacktrace)
selenium.common.exceptions.NoSuchElementException: Message: no such element: Unable to locate element: {"method":"xpath","selector":"//div[@id='root']/div/div[contains(@class,'deepsesarch-dropdown-items')]/div[1]"}
  (Session info: chrome=91.0.4472.124)

2021-07-15 18:39_087260_모바일어플라이언스
Traceback (most recent call last):
  File "C:\Users\kai\PycharmProjects\pythonProject\noname\noname\spiders\noname_spider.py", line 274, in company_scrapy
    button = self.driver.find_element_by_xpath(
  File "c:\users\kai\pycharmprojects\pythonproject\venv\lib\site-packages\selenium\webdriver\remote\webdriver.py", line 394, in find_element_by_xpath
    return self.find_element(by=By.XPATH, value=xpath)
  File "c:\users\kai\pycharmprojects\pythonproject\venv\lib\site-packages\selenium\webdriver\remote\webdriver.py", line 976, in find_element
    return self.execute(Command.FIND_ELEMENT, {
  File "c:\users\kai\pycharmprojects\pythonproject\venv\lib\site-packages\selenium\webdriver\remote\webdriver.py", line 321, in execute
    self.error_handler.check_response(response)
  File "c:\users\kai\pycharmprojects\pythonproject\venv\lib\site-packages\selenium\webdriver\remote\errorhandler.py", line 242, in check_response
    raise exception_class(message, screen, stacktrace)
selenium.common.exceptions.NoSuchElementException: Message: no such element: Unable to locate element: {"method":"xpath","selector":"//div[@id='root']/div/div[contains(@class,'deepsesarch-dropdown-items')]/div[1]"}
  (Session info: chrome=91.0.4472.124)

2021-07-15 18:50_088910_동우팜투테이블
Traceback (most recent call last):
  File "C:\Users\kai\PycharmProjects\pythonProject\noname\noname\spiders\noname_spider.py", line 274, in company_scrapy
    button = self.driver.find_element_by_xpath(
  File "c:\users\kai\pycharmprojects\pythonproject\venv\lib\site-packages\selenium\webdriver\remote\webdriver.py", line 394, in find_element_by_xpath
    return self.find_element(by=By.XPATH, value=xpath)
  File "c:\users\kai\pycharmprojects\pythonproject\venv\lib\site-packages\selenium\webdriver\remote\webdriver.py", line 976, in find_element
    return self.execute(Command.FIND_ELEMENT, {
  File "c:\users\kai\pycharmprojects\pythonproject\venv\lib\site-packages\selenium\webdriver\remote\webdriver.py", line 321, in execute
    self.error_handler.check_response(response)
  File "c:\users\kai\pycharmprojects\pythonproject\venv\lib\site-packages\selenium\webdriver\remote\errorhandler.py", line 242, in check_response
    raise exception_class(message, screen, stacktrace)
selenium.common.exceptions.NoSuchElementException: Message: no such element: Unable to locate element: {"method":"xpath","selector":"//div[@id='root']/div/div[contains(@class,'deepsesarch-dropdown-items')]/div[1]"}
  (Session info: chrome=91.0.4472.124)

2021-07-15 19:16_090470_제이스텍
Traceback (most recent call last):
  File "C:\Users\kai\PycharmProjects\pythonProject\noname\noname\spiders\noname_spider.py", line 274, in company_scrapy
    button = self.driver.find_element_by_xpath(
  File "c:\users\kai\pycharmprojects\pythonproject\venv\lib\site-packages\selenium\webdriver\remote\webdriver.py", line 394, in find_element_by_xpath
    return self.find_element(by=By.XPATH, value=xpath)
  File "c:\users\kai\pycharmprojects\pythonproject\venv\lib\site-packages\selenium\webdriver\remote\webdriver.py", line 976, in find_element
    return self.execute(Command.FIND_ELEMENT, {
  File "c:\users\kai\pycharmprojects\pythonproject\venv\lib\site-packages\selenium\webdriver\remote\webdriver.py", line 321, in execute
    self.error_handler.check_response(response)
  File "c:\users\kai\pycharmprojects\pythonproject\venv\lib\site-packages\selenium\webdriver\remote\errorhandler.py", line 242, in check_response
    raise exception_class(message, screen, stacktrace)
selenium.common.exceptions.NoSuchElementException: Message: no such element: Unable to locate element: {"method":"xpath","selector":"//div[@id='root']/div/div[contains(@class,'deepsesarch-dropdown-items')]/div[1]"}
  (Session info: chrome=91.0.4472.124)

2021-07-15 19:42_092590_럭스피아
Traceback (most recent call last):
  File "C:\Users\kai\PycharmProjects\pythonProject\noname\noname\spiders\noname_spider.py", line 274, in company_scrapy
    button = self.driver.find_element_by_xpath(
  File "c:\users\kai\pycharmprojects\pythonproject\venv\lib\site-packages\selenium\webdriver\remote\webdriver.py", line 394, in find_element_by_xpath
    return self.find_element(by=By.XPATH, value=xpath)
  File "c:\users\kai\pycharmprojects\pythonproject\venv\lib\site-packages\selenium\webdriver\remote\webdriver.py", line 976, in find_element
    return self.execute(Command.FIND_ELEMENT, {
  File "c:\users\kai\pycharmprojects\pythonproject\venv\lib\site-packages\selenium\webdriver\remote\webdriver.py", line 321, in execute
    self.error_handler.check_response(response)
  File "c:\users\kai\pycharmprojects\pythonproject\venv\lib\site-packages\selenium\webdriver\remote\errorhandler.py", line 242, in check_response
    raise exception_class(message, screen, stacktrace)
selenium.common.exceptions.NoSuchElementException: Message: no such element: Unable to locate element: {"method":"xpath","selector":"//div[@id='root']/div/div[contains(@class,'deepsesarch-dropdown-items')]/div[1]"}
  (Session info: chrome=91.0.4472.124)

2021-07-15 19:57_093920_서원인텍
Traceback (most recent call last):
  File "c:\users\kai\pycharmprojects\pythonproject\venv\lib\site-packages\urllib3\connection.py", line 169, in _new_conn
    conn = connection.create_connection(
  File "c:\users\kai\pycharmprojects\pythonproject\venv\lib\site-packages\urllib3\util\connection.py", line 96, in create_connection
    raise err
  File "c:\users\kai\pycharmprojects\pythonproject\venv\lib\site-packages\urllib3\util\connection.py", line 86, in create_connection
    sock.connect(sa)
ConnectionRefusedError: [WinError 10061] 대상 컴퓨터에서 연결을 거부했으므로 연결하지 못했습니다

During handling of the above exception, another exception occurred:

Traceback (most recent call last):
  File "c:\users\kai\pycharmprojects\pythonproject\venv\lib\site-packages\urllib3\connectionpool.py", line 699, in urlopen
    httplib_response = self._make_request(
  File "c:\users\kai\pycharmprojects\pythonproject\venv\lib\site-packages\urllib3\connectionpool.py", line 394, in _make_request
    conn.request(method, url, **httplib_request_kw)
  File "c:\users\kai\pycharmprojects\pythonproject\venv\lib\site-packages\urllib3\connection.py", line 234, in request
    super(HTTPConnection, self).request(method, url, body=body, headers=headers)
  File "C:\Users\kai\AppData\Local\Programs\Python\Python39\lib\http\client.py", line 1253, in request
    self._send_request(method, url, body, headers, encode_chunked)
  File "C:\Users\kai\AppData\Local\Programs\Python\Python39\lib\http\client.py", line 1299, in _send_request
    self.endheaders(body, encode_chunked=encode_chunked)
  File "C:\Users\kai\AppData\Local\Programs\Python\Python39\lib\http\client.py", line 1248, in endheaders
    self._send_output(message_body, encode_chunked=encode_chunked)
  File "C:\Users\kai\AppData\Local\Programs\Python\Python39\lib\http\client.py", line 1008, in _send_output
    self.send(msg)
  File "C:\Users\kai\AppData\Local\Programs\Python\Python39\lib\http\client.py", line 948, in send
    self.connect()
  File "c:\users\kai\pycharmprojects\pythonproject\venv\lib\site-packages\urllib3\connection.py", line 200, in connect
    conn = self._new_conn()
  File "c:\users\kai\pycharmprojects\pythonproject\venv\lib\site-packages\urllib3\connection.py", line 181, in _new_conn
    raise NewConnectionError(
urllib3.exceptions.NewConnectionError: <urllib3.connection.HTTPConnection object at 0x000001E5FFD8DE50>: Failed to establish a new connection: [WinError 10061] 대상 컴퓨터에서 연결을 거부했으므로 연결하지 못했습니다

During handling of the above exception, another exception occurred:

Traceback (most recent call last):
  File "C:\Users\kai\PycharmProjects\pythonProject\noname\noname\spiders\noname_spider.py", line 226, in company_scrapy
    button = self.driver.find_element_by_xpath(
  File "c:\users\kai\pycharmprojects\pythonproject\venv\lib\site-packages\selenium\webdriver\remote\webdriver.py", line 394, in find_element_by_xpath
    return self.find_element(by=By.XPATH, value=xpath)
  File "c:\users\kai\pycharmprojects\pythonproject\venv\lib\site-packages\selenium\webdriver\remote\webdriver.py", line 976, in find_element
    return self.execute(Command.FIND_ELEMENT, {
  File "c:\users\kai\pycharmprojects\pythonproject\venv\lib\site-packages\selenium\webdriver\remote\webdriver.py", line 319, in execute
    response = self.command_executor.execute(driver_command, params)
  File "c:\users\kai\pycharmprojects\pythonproject\venv\lib\site-packages\selenium\webdriver\remote\remote_connection.py", line 374, in execute
    return self._request(command_info[0], url, body=data)
  File "c:\users\kai\pycharmprojects\pythonproject\venv\lib\site-packages\selenium\webdriver\remote\remote_connection.py", line 397, in _request
    resp = self._conn.request(method, url, body=body, headers=headers)
  File "c:\users\kai\pycharmprojects\pythonproject\venv\lib\site-packages\urllib3\request.py", line 78, in request
    return self.request_encode_body(
  File "c:\users\kai\pycharmprojects\pythonproject\venv\lib\site-packages\urllib3\request.py", line 170, in request_encode_body
    return self.urlopen(method, url, **extra_kw)
  File "c:\users\kai\pycharmprojects\pythonproject\venv\lib\site-packages\urllib3\poolmanager.py", line 375, in urlopen
    response = conn.urlopen(method, u.request_uri, **kw)
  File "c:\users\kai\pycharmprojects\pythonproject\venv\lib\site-packages\urllib3\connectionpool.py", line 783, in urlopen
    return self.urlopen(
  File "c:\users\kai\pycharmprojects\pythonproject\venv\lib\site-packages\urllib3\connectionpool.py", line 783, in urlopen
    return self.urlopen(
  File "c:\users\kai\pycharmprojects\pythonproject\venv\lib\site-packages\urllib3\connectionpool.py", line 783, in urlopen
    return self.urlopen(
  File "c:\users\kai\pycharmprojects\pythonproject\venv\lib\site-packages\urllib3\connectionpool.py", line 755, in urlopen
    retries = retries.increment(
  File "c:\users\kai\pycharmprojects\pythonproject\venv\lib\site-packages\urllib3\util\retry.py", line 574, in increment
    raise MaxRetryError(_pool, url, error or ResponseError(cause))
urllib3.exceptions.MaxRetryError: HTTPConnectionPool(host='127.0.0.1', port=49997): Max retries exceeded with url: /session/359abe9da78dd8b8f0cbdde75fdd0e09/element (Caused by NewConnectionError('<urllib3.connection.HTTPConnection object at 0x000001E5FFD8DE50>: Failed to establish a new connection: [WinError 10061] 대상 컴퓨터에서 연결을 거부했으므로 연결하지 못했습니다'))
2021-07-15 19:57_093920_서원인텍
Traceback (most recent call last):
  File "c:\users\kai\pycharmprojects\pythonproject\venv\lib\site-packages\urllib3\connection.py", line 169, in _new_conn
    conn = connection.create_connection(
  File "c:\users\kai\pycharmprojects\pythonproject\venv\lib\site-packages\urllib3\util\connection.py", line 96, in create_connection
    raise err
  File "c:\users\kai\pycharmprojects\pythonproject\venv\lib\site-packages\urllib3\util\connection.py", line 86, in create_connection
    sock.connect(sa)
ConnectionRefusedError: [WinError 10061] 대상 컴퓨터에서 연결을 거부했으므로 연결하지 못했습니다

During handling of the above exception, another exception occurred:

Traceback (most recent call last):
  File "c:\users\kai\pycharmprojects\pythonproject\venv\lib\site-packages\urllib3\connectionpool.py", line 699, in urlopen
    httplib_response = self._make_request(
  File "c:\users\kai\pycharmprojects\pythonproject\venv\lib\site-packages\urllib3\connectionpool.py", line 394, in _make_request
    conn.request(method, url, **httplib_request_kw)
  File "c:\users\kai\pycharmprojects\pythonproject\venv\lib\site-packages\urllib3\connection.py", line 234, in request
    super(HTTPConnection, self).request(method, url, body=body, headers=headers)
  File "C:\Users\kai\AppData\Local\Programs\Python\Python39\lib\http\client.py", line 1253, in request
    self._send_request(method, url, body, headers, encode_chunked)
  File "C:\Users\kai\AppData\Local\Programs\Python\Python39\lib\http\client.py", line 1299, in _send_request
    self.endheaders(body, encode_chunked=encode_chunked)
  File "C:\Users\kai\AppData\Local\Programs\Python\Python39\lib\http\client.py", line 1248, in endheaders
    self._send_output(message_body, encode_chunked=encode_chunked)
  File "C:\Users\kai\AppData\Local\Programs\Python\Python39\lib\http\client.py", line 1008, in _send_output
    self.send(msg)
  File "C:\Users\kai\AppData\Local\Programs\Python\Python39\lib\http\client.py", line 948, in send
    self.connect()
  File "c:\users\kai\pycharmprojects\pythonproject\venv\lib\site-packages\urllib3\connection.py", line 200, in connect
    conn = self._new_conn()
  File "c:\users\kai\pycharmprojects\pythonproject\venv\lib\site-packages\urllib3\connection.py", line 181, in _new_conn
    raise NewConnectionError(
urllib3.exceptions.NewConnectionError: <urllib3.connection.HTTPConnection object at 0x000001E597801C40>: Failed to establish a new connection: [WinError 10061] 대상 컴퓨터에서 연결을 거부했으므로 연결하지 못했습니다

During handling of the above exception, another exception occurred:

Traceback (most recent call last):
  File "C:\Users\kai\PycharmProjects\pythonProject\noname\noname\spiders\noname_spider.py", line 127, in company_scrapy
    menu1_button = self.driver.find_element_by_xpath(
  File "c:\users\kai\pycharmprojects\pythonproject\venv\lib\site-packages\selenium\webdriver\remote\webdriver.py", line 394, in find_element_by_xpath
    return self.find_element(by=By.XPATH, value=xpath)
  File "c:\users\kai\pycharmprojects\pythonproject\venv\lib\site-packages\selenium\webdriver\remote\webdriver.py", line 976, in find_element
    return self.execute(Command.FIND_ELEMENT, {
  File "c:\users\kai\pycharmprojects\pythonproject\venv\lib\site-packages\selenium\webdriver\remote\webdriver.py", line 319, in execute
    response = self.command_executor.execute(driver_command, params)
  File "c:\users\kai\pycharmprojects\pythonproject\venv\lib\site-packages\selenium\webdriver\remote\remote_connection.py", line 374, in execute
    return self._request(command_info[0], url, body=data)
  File "c:\users\kai\pycharmprojects\pythonproject\venv\lib\site-packages\selenium\webdriver\remote\remote_connection.py", line 397, in _request
    resp = self._conn.request(method, url, body=body, headers=headers)
  File "c:\users\kai\pycharmprojects\pythonproject\venv\lib\site-packages\urllib3\request.py", line 78, in request
    return self.request_encode_body(
  File "c:\users\kai\pycharmprojects\pythonproject\venv\lib\site-packages\urllib3\request.py", line 170, in request_encode_body
    return self.urlopen(method, url, **extra_kw)
  File "c:\users\kai\pycharmprojects\pythonproject\venv\lib\site-packages\urllib3\poolmanager.py", line 375, in urlopen
    response = conn.urlopen(method, u.request_uri, **kw)
  File "c:\users\kai\pycharmprojects\pythonproject\venv\lib\site-packages\urllib3\connectionpool.py", line 783, in urlopen
    return self.urlopen(
  File "c:\users\kai\pycharmprojects\pythonproject\venv\lib\site-packages\urllib3\connectionpool.py", line 783, in urlopen
    return self.urlopen(
  File "c:\users\kai\pycharmprojects\pythonproject\venv\lib\site-packages\urllib3\connectionpool.py", line 783, in urlopen
    return self.urlopen(
  File "c:\users\kai\pycharmprojects\pythonproject\venv\lib\site-packages\urllib3\connectionpool.py", line 755, in urlopen
    retries = retries.increment(
  File "c:\users\kai\pycharmprojects\pythonproject\venv\lib\site-packages\urllib3\util\retry.py", line 574, in increment
    raise MaxRetryError(_pool, url, error or ResponseError(cause))
urllib3.exceptions.MaxRetryError: HTTPConnectionPool(host='127.0.0.1', port=49997): Max retries exceeded with url: /session/359abe9da78dd8b8f0cbdde75fdd0e09/element (Caused by NewConnectionError('<urllib3.connection.HTTPConnection object at 0x000001E597801C40>: Failed to establish a new connection: [WinError 10061] 대상 컴퓨터에서 연결을 거부했으므로 연결하지 못했습니다'))
2021-07-15 19:57_093920_서원인텍
Traceback (most recent call last):
  File "c:\users\kai\pycharmprojects\pythonproject\venv\lib\site-packages\urllib3\connection.py", line 169, in _new_conn
    conn = connection.create_connection(
  File "c:\users\kai\pycharmprojects\pythonproject\venv\lib\site-packages\urllib3\util\connection.py", line 96, in create_connection
    raise err
  File "c:\users\kai\pycharmprojects\pythonproject\venv\lib\site-packages\urllib3\util\connection.py", line 86, in create_connection
    sock.connect(sa)
ConnectionRefusedError: [WinError 10061] 대상 컴퓨터에서 연결을 거부했으므로 연결하지 못했습니다

During handling of the above exception, another exception occurred:

Traceback (most recent call last):
  File "c:\users\kai\pycharmprojects\pythonproject\venv\lib\site-packages\urllib3\connectionpool.py", line 699, in urlopen
    httplib_response = self._make_request(
  File "c:\users\kai\pycharmprojects\pythonproject\venv\lib\site-packages\urllib3\connectionpool.py", line 394, in _make_request
    conn.request(method, url, **httplib_request_kw)
  File "c:\users\kai\pycharmprojects\pythonproject\venv\lib\site-packages\urllib3\connection.py", line 234, in request
    super(HTTPConnection, self).request(method, url, body=body, headers=headers)
  File "C:\Users\kai\AppData\Local\Programs\Python\Python39\lib\http\client.py", line 1253, in request
    self._send_request(method, url, body, headers, encode_chunked)
  File "C:\Users\kai\AppData\Local\Programs\Python\Python39\lib\http\client.py", line 1299, in _send_request
    self.endheaders(body, encode_chunked=encode_chunked)
  File "C:\Users\kai\AppData\Local\Programs\Python\Python39\lib\http\client.py", line 1248, in endheaders
    self._send_output(message_body, encode_chunked=encode_chunked)
  File "C:\Users\kai\AppData\Local\Programs\Python\Python39\lib\http\client.py", line 1008, in _send_output
    self.send(msg)
  File "C:\Users\kai\AppData\Local\Programs\Python\Python39\lib\http\client.py", line 948, in send
    self.connect()
  File "c:\users\kai\pycharmprojects\pythonproject\venv\lib\site-packages\urllib3\connection.py", line 200, in connect
    conn = self._new_conn()
  File "c:\users\kai\pycharmprojects\pythonproject\venv\lib\site-packages\urllib3\connection.py", line 181, in _new_conn
    raise NewConnectionError(
urllib3.exceptions.NewConnectionError: <urllib3.connection.HTTPConnection object at 0x000001E5977CACA0>: Failed to establish a new connection: [WinError 10061] 대상 컴퓨터에서 연결을 거부했으므로 연결하지 못했습니다

During handling of the above exception, another exception occurred:

Traceback (most recent call last):
  File "C:\Users\kai\PycharmProjects\pythonProject\noname\noname\spiders\noname_spider.py", line 127, in company_scrapy
    menu1_button = self.driver.find_element_by_xpath(
  File "c:\users\kai\pycharmprojects\pythonproject\venv\lib\site-packages\selenium\webdriver\remote\webdriver.py", line 394, in find_element_by_xpath
    return self.find_element(by=By.XPATH, value=xpath)
  File "c:\users\kai\pycharmprojects\pythonproject\venv\lib\site-packages\selenium\webdriver\remote\webdriver.py", line 976, in find_element
    return self.execute(Command.FIND_ELEMENT, {
  File "c:\users\kai\pycharmprojects\pythonproject\venv\lib\site-packages\selenium\webdriver\remote\webdriver.py", line 319, in execute
    response = self.command_executor.execute(driver_command, params)
  File "c:\users\kai\pycharmprojects\pythonproject\venv\lib\site-packages\selenium\webdriver\remote\remote_connection.py", line 374, in execute
    return self._request(command_info[0], url, body=data)
  File "c:\users\kai\pycharmprojects\pythonproject\venv\lib\site-packages\selenium\webdriver\remote\remote_connection.py", line 397, in _request
    resp = self._conn.request(method, url, body=body, headers=headers)
  File "c:\users\kai\pycharmprojects\pythonproject\venv\lib\site-packages\urllib3\request.py", line 78, in request
    return self.request_encode_body(
  File "c:\users\kai\pycharmprojects\pythonproject\venv\lib\site-packages\urllib3\request.py", line 170, in request_encode_body
    return self.urlopen(method, url, **extra_kw)
  File "c:\users\kai\pycharmprojects\pythonproject\venv\lib\site-packages\urllib3\poolmanager.py", line 375, in urlopen
    response = conn.urlopen(method, u.request_uri, **kw)
  File "c:\users\kai\pycharmprojects\pythonproject\venv\lib\site-packages\urllib3\connectionpool.py", line 783, in urlopen
    return self.urlopen(
  File "c:\users\kai\pycharmprojects\pythonproject\venv\lib\site-packages\urllib3\connectionpool.py", line 783, in urlopen
    return self.urlopen(
  File "c:\users\kai\pycharmprojects\pythonproject\venv\lib\site-packages\urllib3\connectionpool.py", line 783, in urlopen
    return self.urlopen(
  File "c:\users\kai\pycharmprojects\pythonproject\venv\lib\site-packages\urllib3\connectionpool.py", line 755, in urlopen
    retries = retries.increment(
  File "c:\users\kai\pycharmprojects\pythonproject\venv\lib\site-packages\urllib3\util\retry.py", line 574, in increment
    raise MaxRetryError(_pool, url, error or ResponseError(cause))
urllib3.exceptions.MaxRetryError: HTTPConnectionPool(host='127.0.0.1', port=49997): Max retries exceeded with url: /session/359abe9da78dd8b8f0cbdde75fdd0e09/element (Caused by NewConnectionError('<urllib3.connection.HTTPConnection object at 0x000001E5977CACA0>: Failed to establish a new connection: [WinError 10061] 대상 컴퓨터에서 연결을 거부했으므로 연결하지 못했습니다'))
2021-07-15 19:57_094170_동운아나텍
Traceback (most recent call last):
  File "c:\users\kai\pycharmprojects\pythonproject\venv\lib\site-packages\urllib3\connection.py", line 169, in _new_conn
    conn = connection.create_connection(
  File "c:\users\kai\pycharmprojects\pythonproject\venv\lib\site-packages\urllib3\util\connection.py", line 96, in create_connection
    raise err
  File "c:\users\kai\pycharmprojects\pythonproject\venv\lib\site-packages\urllib3\util\connection.py", line 86, in create_connection
    sock.connect(sa)
ConnectionRefusedError: [WinError 10061] 대상 컴퓨터에서 연결을 거부했으므로 연결하지 못했습니다

During handling of the above exception, another exception occurred:

Traceback (most recent call last):
  File "c:\users\kai\pycharmprojects\pythonproject\venv\lib\site-packages\urllib3\connectionpool.py", line 699, in urlopen
    httplib_response = self._make_request(
  File "c:\users\kai\pycharmprojects\pythonproject\venv\lib\site-packages\urllib3\connectionpool.py", line 394, in _make_request
    conn.request(method, url, **httplib_request_kw)
  File "c:\users\kai\pycharmprojects\pythonproject\venv\lib\site-packages\urllib3\connection.py", line 234, in request
    super(HTTPConnection, self).request(method, url, body=body, headers=headers)
  File "C:\Users\kai\AppData\Local\Programs\Python\Python39\lib\http\client.py", line 1253, in request
    self._send_request(method, url, body, headers, encode_chunked)
  File "C:\Users\kai\AppData\Local\Programs\Python\Python39\lib\http\client.py", line 1299, in _send_request
    self.endheaders(body, encode_chunked=encode_chunked)
  File "C:\Users\kai\AppData\Local\Programs\Python\Python39\lib\http\client.py", line 1248, in endheaders
    self._send_output(message_body, encode_chunked=encode_chunked)
  File "C:\Users\kai\AppData\Local\Programs\Python\Python39\lib\http\client.py", line 1008, in _send_output
    self.send(msg)
  File "C:\Users\kai\AppData\Local\Programs\Python\Python39\lib\http\client.py", line 948, in send
    self.connect()
  File "c:\users\kai\pycharmprojects\pythonproject\venv\lib\site-packages\urllib3\connection.py", line 200, in connect
    conn = self._new_conn()
  File "c:\users\kai\pycharmprojects\pythonproject\venv\lib\site-packages\urllib3\connection.py", line 181, in _new_conn
    raise NewConnectionError(
urllib3.exceptions.NewConnectionError: <urllib3.connection.HTTPConnection object at 0x000001E59786DD90>: Failed to establish a new connection: [WinError 10061] 대상 컴퓨터에서 연결을 거부했으므로 연결하지 못했습니다

During handling of the above exception, another exception occurred:

Traceback (most recent call last):
  File "C:\Users\kai\PycharmProjects\pythonProject\noname\noname\spiders\noname_spider.py", line 127, in company_scrapy
    menu1_button = self.driver.find_element_by_xpath(
  File "c:\users\kai\pycharmprojects\pythonproject\venv\lib\site-packages\selenium\webdriver\remote\webdriver.py", line 394, in find_element_by_xpath
    return self.find_element(by=By.XPATH, value=xpath)
  File "c:\users\kai\pycharmprojects\pythonproject\venv\lib\site-packages\selenium\webdriver\remote\webdriver.py", line 976, in find_element
    return self.execute(Command.FIND_ELEMENT, {
  File "c:\users\kai\pycharmprojects\pythonproject\venv\lib\site-packages\selenium\webdriver\remote\webdriver.py", line 319, in execute
    response = self.command_executor.execute(driver_command, params)
  File "c:\users\kai\pycharmprojects\pythonproject\venv\lib\site-packages\selenium\webdriver\remote\remote_connection.py", line 374, in execute
    return self._request(command_info[0], url, body=data)
  File "c:\users\kai\pycharmprojects\pythonproject\venv\lib\site-packages\selenium\webdriver\remote\remote_connection.py", line 397, in _request
    resp = self._conn.request(method, url, body=body, headers=headers)
  File "c:\users\kai\pycharmprojects\pythonproject\venv\lib\site-packages\urllib3\request.py", line 78, in request
    return self.request_encode_body(
  File "c:\users\kai\pycharmprojects\pythonproject\venv\lib\site-packages\urllib3\request.py", line 170, in request_encode_body
    return self.urlopen(method, url, **extra_kw)
  File "c:\users\kai\pycharmprojects\pythonproject\venv\lib\site-packages\urllib3\poolmanager.py", line 375, in urlopen
    response = conn.urlopen(method, u.request_uri, **kw)
  File "c:\users\kai\pycharmprojects\pythonproject\venv\lib\site-packages\urllib3\connectionpool.py", line 783, in urlopen
    return self.urlopen(
  File "c:\users\kai\pycharmprojects\pythonproject\venv\lib\site-packages\urllib3\connectionpool.py", line 783, in urlopen
    return self.urlopen(
  File "c:\users\kai\pycharmprojects\pythonproject\venv\lib\site-packages\urllib3\connectionpool.py", line 783, in urlopen
    return self.urlopen(
  File "c:\users\kai\pycharmprojects\pythonproject\venv\lib\site-packages\urllib3\connectionpool.py", line 755, in urlopen
    retries = retries.increment(
  File "c:\users\kai\pycharmprojects\pythonproject\venv\lib\site-packages\urllib3\util\retry.py", line 574, in increment
    raise MaxRetryError(_pool, url, error or ResponseError(cause))
urllib3.exceptions.MaxRetryError: HTTPConnectionPool(host='127.0.0.1', port=49997): Max retries exceeded with url: /session/359abe9da78dd8b8f0cbdde75fdd0e09/element (Caused by NewConnectionError('<urllib3.connection.HTTPConnection object at 0x000001E59786DD90>: Failed to establish a new connection: [WinError 10061] 대상 컴퓨터에서 연결을 거부했으므로 연결하지 못했습니다'))
2021-07-15 19:57_094170_동운아나텍
Traceback (most recent call last):
  File "c:\users\kai\pycharmprojects\pythonproject\venv\lib\site-packages\urllib3\connection.py", line 169, in _new_conn
    conn = connection.create_connection(
  File "c:\users\kai\pycharmprojects\pythonproject\venv\lib\site-packages\urllib3\util\connection.py", line 96, in create_connection
    raise err
  File "c:\users\kai\pycharmprojects\pythonproject\venv\lib\site-packages\urllib3\util\connection.py", line 86, in create_connection
    sock.connect(sa)
ConnectionRefusedError: [WinError 10061] 대상 컴퓨터에서 연결을 거부했으므로 연결하지 못했습니다

During handling of the above exception, another exception occurred:

Traceback (most recent call last):
  File "c:\users\kai\pycharmprojects\pythonproject\venv\lib\site-packages\urllib3\connectionpool.py", line 699, in urlopen
    httplib_response = self._make_request(
  File "c:\users\kai\pycharmprojects\pythonproject\venv\lib\site-packages\urllib3\connectionpool.py", line 394, in _make_request
    conn.request(method, url, **httplib_request_kw)
  File "c:\users\kai\pycharmprojects\pythonproject\venv\lib\site-packages\urllib3\connection.py", line 234, in request
    super(HTTPConnection, self).request(method, url, body=body, headers=headers)
  File "C:\Users\kai\AppData\Local\Programs\Python\Python39\lib\http\client.py", line 1253, in request
    self._send_request(method, url, body, headers, encode_chunked)
  File "C:\Users\kai\AppData\Local\Programs\Python\Python39\lib\http\client.py", line 1299, in _send_request
    self.endheaders(body, encode_chunked=encode_chunked)
  File "C:\Users\kai\AppData\Local\Programs\Python\Python39\lib\http\client.py", line 1248, in endheaders
    self._send_output(message_body, encode_chunked=encode_chunked)
  File "C:\Users\kai\AppData\Local\Programs\Python\Python39\lib\http\client.py", line 1008, in _send_output
    self.send(msg)
  File "C:\Users\kai\AppData\Local\Programs\Python\Python39\lib\http\client.py", line 948, in send
    self.connect()
  File "c:\users\kai\pycharmprojects\pythonproject\venv\lib\site-packages\urllib3\connection.py", line 200, in connect
    conn = self._new_conn()
  File "c:\users\kai\pycharmprojects\pythonproject\venv\lib\site-packages\urllib3\connection.py", line 181, in _new_conn
    raise NewConnectionError(
urllib3.exceptions.NewConnectionError: <urllib3.connection.HTTPConnection object at 0x000001E59786D040>: Failed to establish a new connection: [WinError 10061] 대상 컴퓨터에서 연결을 거부했으므로 연결하지 못했습니다

During handling of the above exception, another exception occurred:

Traceback (most recent call last):
  File "C:\Users\kai\PycharmProjects\pythonProject\noname\noname\spiders\noname_spider.py", line 127, in company_scrapy
    menu1_button = self.driver.find_element_by_xpath(
  File "c:\users\kai\pycharmprojects\pythonproject\venv\lib\site-packages\selenium\webdriver\remote\webdriver.py", line 394, in find_element_by_xpath
    return self.find_element(by=By.XPATH, value=xpath)
  File "c:\users\kai\pycharmprojects\pythonproject\venv\lib\site-packages\selenium\webdriver\remote\webdriver.py", line 976, in find_element
    return self.execute(Command.FIND_ELEMENT, {
  File "c:\users\kai\pycharmprojects\pythonproject\venv\lib\site-packages\selenium\webdriver\remote\webdriver.py", line 319, in execute
    response = self.command_executor.execute(driver_command, params)
  File "c:\users\kai\pycharmprojects\pythonproject\venv\lib\site-packages\selenium\webdriver\remote\remote_connection.py", line 374, in execute
    return self._request(command_info[0], url, body=data)
  File "c:\users\kai\pycharmprojects\pythonproject\venv\lib\site-packages\selenium\webdriver\remote\remote_connection.py", line 397, in _request
    resp = self._conn.request(method, url, body=body, headers=headers)
  File "c:\users\kai\pycharmprojects\pythonproject\venv\lib\site-packages\urllib3\request.py", line 78, in request
    return self.request_encode_body(
  File "c:\users\kai\pycharmprojects\pythonproject\venv\lib\site-packages\urllib3\request.py", line 170, in request_encode_body
    return self.urlopen(method, url, **extra_kw)
  File "c:\users\kai\pycharmprojects\pythonproject\venv\lib\site-packages\urllib3\poolmanager.py", line 375, in urlopen
    response = conn.urlopen(method, u.request_uri, **kw)
  File "c:\users\kai\pycharmprojects\pythonproject\venv\lib\site-packages\urllib3\connectionpool.py", line 783, in urlopen
    return self.urlopen(
  File "c:\users\kai\pycharmprojects\pythonproject\venv\lib\site-packages\urllib3\connectionpool.py", line 783, in urlopen
    return self.urlopen(
  File "c:\users\kai\pycharmprojects\pythonproject\venv\lib\site-packages\urllib3\connectionpool.py", line 783, in urlopen
    return self.urlopen(
  File "c:\users\kai\pycharmprojects\pythonproject\venv\lib\site-packages\urllib3\connectionpool.py", line 755, in urlopen
    retries = retries.increment(
  File "c:\users\kai\pycharmprojects\pythonproject\venv\lib\site-packages\urllib3\util\retry.py", line 574, in increment
    raise MaxRetryError(_pool, url, error or ResponseError(cause))
urllib3.exceptions.MaxRetryError: HTTPConnectionPool(host='127.0.0.1', port=49997): Max retries exceeded with url: /session/359abe9da78dd8b8f0cbdde75fdd0e09/element (Caused by NewConnectionError('<urllib3.connection.HTTPConnection object at 0x000001E59786D040>: Failed to establish a new connection: [WinError 10061] 대상 컴퓨터에서 연결을 거부했으므로 연결하지 못했습니다'))
2021-07-15 19:58_094170_동운아나텍
Traceback (most recent call last):
  File "c:\users\kai\pycharmprojects\pythonproject\venv\lib\site-packages\urllib3\connection.py", line 169, in _new_conn
    conn = connection.create_connection(
  File "c:\users\kai\pycharmprojects\pythonproject\venv\lib\site-packages\urllib3\util\connection.py", line 96, in create_connection
    raise err
  File "c:\users\kai\pycharmprojects\pythonproject\venv\lib\site-packages\urllib3\util\connection.py", line 86, in create_connection
    sock.connect(sa)
ConnectionRefusedError: [WinError 10061] 대상 컴퓨터에서 연결을 거부했으므로 연결하지 못했습니다

During handling of the above exception, another exception occurred:

Traceback (most recent call last):
  File "c:\users\kai\pycharmprojects\pythonproject\venv\lib\site-packages\urllib3\connectionpool.py", line 699, in urlopen
    httplib_response = self._make_request(
  File "c:\users\kai\pycharmprojects\pythonproject\venv\lib\site-packages\urllib3\connectionpool.py", line 394, in _make_request
    conn.request(method, url, **httplib_request_kw)
  File "c:\users\kai\pycharmprojects\pythonproject\venv\lib\site-packages\urllib3\connection.py", line 234, in request
    super(HTTPConnection, self).request(method, url, body=body, headers=headers)
  File "C:\Users\kai\AppData\Local\Programs\Python\Python39\lib\http\client.py", line 1253, in request
    self._send_request(method, url, body, headers, encode_chunked)
  File "C:\Users\kai\AppData\Local\Programs\Python\Python39\lib\http\client.py", line 1299, in _send_request
    self.endheaders(body, encode_chunked=encode_chunked)
  File "C:\Users\kai\AppData\Local\Programs\Python\Python39\lib\http\client.py", line 1248, in endheaders
    self._send_output(message_body, encode_chunked=encode_chunked)
  File "C:\Users\kai\AppData\Local\Programs\Python\Python39\lib\http\client.py", line 1008, in _send_output
    self.send(msg)
  File "C:\Users\kai\AppData\Local\Programs\Python\Python39\lib\http\client.py", line 948, in send
    self.connect()
  File "c:\users\kai\pycharmprojects\pythonproject\venv\lib\site-packages\urllib3\connection.py", line 200, in connect
    conn = self._new_conn()
  File "c:\users\kai\pycharmprojects\pythonproject\venv\lib\site-packages\urllib3\connection.py", line 181, in _new_conn
    raise NewConnectionError(
urllib3.exceptions.NewConnectionError: <urllib3.connection.HTTPConnection object at 0x000001E5977CAE20>: Failed to establish a new connection: [WinError 10061] 대상 컴퓨터에서 연결을 거부했으므로 연결하지 못했습니다

During handling of the above exception, another exception occurred:

Traceback (most recent call last):
  File "C:\Users\kai\PycharmProjects\pythonProject\noname\noname\spiders\noname_spider.py", line 127, in company_scrapy
    menu1_button = self.driver.find_element_by_xpath(
  File "c:\users\kai\pycharmprojects\pythonproject\venv\lib\site-packages\selenium\webdriver\remote\webdriver.py", line 394, in find_element_by_xpath
    return self.find_element(by=By.XPATH, value=xpath)
  File "c:\users\kai\pycharmprojects\pythonproject\venv\lib\site-packages\selenium\webdriver\remote\webdriver.py", line 976, in find_element
    return self.execute(Command.FIND_ELEMENT, {
  File "c:\users\kai\pycharmprojects\pythonproject\venv\lib\site-packages\selenium\webdriver\remote\webdriver.py", line 319, in execute
    response = self.command_executor.execute(driver_command, params)
  File "c:\users\kai\pycharmprojects\pythonproject\venv\lib\site-packages\selenium\webdriver\remote\remote_connection.py", line 374, in execute
    return self._request(command_info[0], url, body=data)
  File "c:\users\kai\pycharmprojects\pythonproject\venv\lib\site-packages\selenium\webdriver\remote\remote_connection.py", line 397, in _request
    resp = self._conn.request(method, url, body=body, headers=headers)
  File "c:\users\kai\pycharmprojects\pythonproject\venv\lib\site-packages\urllib3\request.py", line 78, in request
    return self.request_encode_body(
  File "c:\users\kai\pycharmprojects\pythonproject\venv\lib\site-packages\urllib3\request.py", line 170, in request_encode_body
    return self.urlopen(method, url, **extra_kw)
  File "c:\users\kai\pycharmprojects\pythonproject\venv\lib\site-packages\urllib3\poolmanager.py", line 375, in urlopen
    response = conn.urlopen(method, u.request_uri, **kw)
  File "c:\users\kai\pycharmprojects\pythonproject\venv\lib\site-packages\urllib3\connectionpool.py", line 783, in urlopen
    return self.urlopen(
  File "c:\users\kai\pycharmprojects\pythonproject\venv\lib\site-packages\urllib3\connectionpool.py", line 783, in urlopen
    return self.urlopen(
  File "c:\users\kai\pycharmprojects\pythonproject\venv\lib\site-packages\urllib3\connectionpool.py", line 783, in urlopen
    return self.urlopen(
  File "c:\users\kai\pycharmprojects\pythonproject\venv\lib\site-packages\urllib3\connectionpool.py", line 755, in urlopen
    retries = retries.increment(
  File "c:\users\kai\pycharmprojects\pythonproject\venv\lib\site-packages\urllib3\util\retry.py", line 574, in increment
    raise MaxRetryError(_pool, url, error or ResponseError(cause))
urllib3.exceptions.MaxRetryError: HTTPConnectionPool(host='127.0.0.1', port=49997): Max retries exceeded with url: /session/359abe9da78dd8b8f0cbdde75fdd0e09/element (Caused by NewConnectionError('<urllib3.connection.HTTPConnection object at 0x000001E5977CAE20>: Failed to establish a new connection: [WinError 10061] 대상 컴퓨터에서 연결을 거부했으므로 연결하지 못했습니다'))
2021-07-15 19:58_094360_칩스앤미디어
Traceback (most recent call last):
  File "c:\users\kai\pycharmprojects\pythonproject\venv\lib\site-packages\urllib3\connection.py", line 169, in _new_conn
    conn = connection.create_connection(
  File "c:\users\kai\pycharmprojects\pythonproject\venv\lib\site-packages\urllib3\util\connection.py", line 96, in create_connection
    raise err
  File "c:\users\kai\pycharmprojects\pythonproject\venv\lib\site-packages\urllib3\util\connection.py", line 86, in create_connection
    sock.connect(sa)
ConnectionRefusedError: [WinError 10061] 대상 컴퓨터에서 연결을 거부했으므로 연결하지 못했습니다

During handling of the above exception, another exception occurred:

Traceback (most recent call last):
  File "c:\users\kai\pycharmprojects\pythonproject\venv\lib\site-packages\urllib3\connectionpool.py", line 699, in urlopen
    httplib_response = self._make_request(
  File "c:\users\kai\pycharmprojects\pythonproject\venv\lib\site-packages\urllib3\connectionpool.py", line 394, in _make_request
    conn.request(method, url, **httplib_request_kw)
  File "c:\users\kai\pycharmprojects\pythonproject\venv\lib\site-packages\urllib3\connection.py", line 234, in request
    super(HTTPConnection, self).request(method, url, body=body, headers=headers)
  File "C:\Users\kai\AppData\Local\Programs\Python\Python39\lib\http\client.py", line 1253, in request
    self._send_request(method, url, body, headers, encode_chunked)
  File "C:\Users\kai\AppData\Local\Programs\Python\Python39\lib\http\client.py", line 1299, in _send_request
    self.endheaders(body, encode_chunked=encode_chunked)
  File "C:\Users\kai\AppData\Local\Programs\Python\Python39\lib\http\client.py", line 1248, in endheaders
    self._send_output(message_body, encode_chunked=encode_chunked)
  File "C:\Users\kai\AppData\Local\Programs\Python\Python39\lib\http\client.py", line 1008, in _send_output
    self.send(msg)
  File "C:\Users\kai\AppData\Local\Programs\Python\Python39\lib\http\client.py", line 948, in send
    self.connect()
  File "c:\users\kai\pycharmprojects\pythonproject\venv\lib\site-packages\urllib3\connection.py", line 200, in connect
    conn = self._new_conn()
  File "c:\users\kai\pycharmprojects\pythonproject\venv\lib\site-packages\urllib3\connection.py", line 181, in _new_conn
    raise NewConnectionError(
urllib3.exceptions.NewConnectionError: <urllib3.connection.HTTPConnection object at 0x000001E597801BB0>: Failed to establish a new connection: [WinError 10061] 대상 컴퓨터에서 연결을 거부했으므로 연결하지 못했습니다

During handling of the above exception, another exception occurred:

Traceback (most recent call last):
  File "C:\Users\kai\PycharmProjects\pythonProject\noname\noname\spiders\noname_spider.py", line 127, in company_scrapy
    menu1_button = self.driver.find_element_by_xpath(
  File "c:\users\kai\pycharmprojects\pythonproject\venv\lib\site-packages\selenium\webdriver\remote\webdriver.py", line 394, in find_element_by_xpath
    return self.find_element(by=By.XPATH, value=xpath)
  File "c:\users\kai\pycharmprojects\pythonproject\venv\lib\site-packages\selenium\webdriver\remote\webdriver.py", line 976, in find_element
    return self.execute(Command.FIND_ELEMENT, {
  File "c:\users\kai\pycharmprojects\pythonproject\venv\lib\site-packages\selenium\webdriver\remote\webdriver.py", line 319, in execute
    response = self.command_executor.execute(driver_command, params)
  File "c:\users\kai\pycharmprojects\pythonproject\venv\lib\site-packages\selenium\webdriver\remote\remote_connection.py", line 374, in execute
    return self._request(command_info[0], url, body=data)
  File "c:\users\kai\pycharmprojects\pythonproject\venv\lib\site-packages\selenium\webdriver\remote\remote_connection.py", line 397, in _request
    resp = self._conn.request(method, url, body=body, headers=headers)
  File "c:\users\kai\pycharmprojects\pythonproject\venv\lib\site-packages\urllib3\request.py", line 78, in request
    return self.request_encode_body(
  File "c:\users\kai\pycharmprojects\pythonproject\venv\lib\site-packages\urllib3\request.py", line 170, in request_encode_body
    return self.urlopen(method, url, **extra_kw)
  File "c:\users\kai\pycharmprojects\pythonproject\venv\lib\site-packages\urllib3\poolmanager.py", line 375, in urlopen
    response = conn.urlopen(method, u.request_uri, **kw)
  File "c:\users\kai\pycharmprojects\pythonproject\venv\lib\site-packages\urllib3\connectionpool.py", line 783, in urlopen
    return self.urlopen(
  File "c:\users\kai\pycharmprojects\pythonproject\venv\lib\site-packages\urllib3\connectionpool.py", line 783, in urlopen
    return self.urlopen(
  File "c:\users\kai\pycharmprojects\pythonproject\venv\lib\site-packages\urllib3\connectionpool.py", line 783, in urlopen
    return self.urlopen(
  File "c:\users\kai\pycharmprojects\pythonproject\venv\lib\site-packages\urllib3\connectionpool.py", line 755, in urlopen
    retries = retries.increment(
  File "c:\users\kai\pycharmprojects\pythonproject\venv\lib\site-packages\urllib3\util\retry.py", line 574, in increment
    raise MaxRetryError(_pool, url, error or ResponseError(cause))
urllib3.exceptions.MaxRetryError: HTTPConnectionPool(host='127.0.0.1', port=49997): Max retries exceeded with url: /session/359abe9da78dd8b8f0cbdde75fdd0e09/element (Caused by NewConnectionError('<urllib3.connection.HTTPConnection object at 0x000001E597801BB0>: Failed to establish a new connection: [WinError 10061] 대상 컴퓨터에서 연결을 거부했으므로 연결하지 못했습니다'))
2021-07-15 19:58_094360_칩스앤미디어
Traceback (most recent call last):
  File "c:\users\kai\pycharmprojects\pythonproject\venv\lib\site-packages\urllib3\connection.py", line 169, in _new_conn
    conn = connection.create_connection(
  File "c:\users\kai\pycharmprojects\pythonproject\venv\lib\site-packages\urllib3\util\connection.py", line 96, in create_connection
    raise err
  File "c:\users\kai\pycharmprojects\pythonproject\venv\lib\site-packages\urllib3\util\connection.py", line 86, in create_connection
    sock.connect(sa)
ConnectionRefusedError: [WinError 10061] 대상 컴퓨터에서 연결을 거부했으므로 연결하지 못했습니다

During handling of the above exception, another exception occurred:

Traceback (most recent call last):
  File "c:\users\kai\pycharmprojects\pythonproject\venv\lib\site-packages\urllib3\connectionpool.py", line 699, in urlopen
    httplib_response = self._make_request(
  File "c:\users\kai\pycharmprojects\pythonproject\venv\lib\site-packages\urllib3\connectionpool.py", line 394, in _make_request
    conn.request(method, url, **httplib_request_kw)
  File "c:\users\kai\pycharmprojects\pythonproject\venv\lib\site-packages\urllib3\connection.py", line 234, in request
    super(HTTPConnection, self).request(method, url, body=body, headers=headers)
  File "C:\Users\kai\AppData\Local\Programs\Python\Python39\lib\http\client.py", line 1253, in request
    self._send_request(method, url, body, headers, encode_chunked)
  File "C:\Users\kai\AppData\Local\Programs\Python\Python39\lib\http\client.py", line 1299, in _send_request
    self.endheaders(body, encode_chunked=encode_chunked)
  File "C:\Users\kai\AppData\Local\Programs\Python\Python39\lib\http\client.py", line 1248, in endheaders
    self._send_output(message_body, encode_chunked=encode_chunked)
  File "C:\Users\kai\AppData\Local\Programs\Python\Python39\lib\http\client.py", line 1008, in _send_output
    self.send(msg)
  File "C:\Users\kai\AppData\Local\Programs\Python\Python39\lib\http\client.py", line 948, in send
    self.connect()
  File "c:\users\kai\pycharmprojects\pythonproject\venv\lib\site-packages\urllib3\connection.py", line 200, in connect
    conn = self._new_conn()
  File "c:\users\kai\pycharmprojects\pythonproject\venv\lib\site-packages\urllib3\connection.py", line 181, in _new_conn
    raise NewConnectionError(
urllib3.exceptions.NewConnectionError: <urllib3.connection.HTTPConnection object at 0x000001E5978EE1C0>: Failed to establish a new connection: [WinError 10061] 대상 컴퓨터에서 연결을 거부했으므로 연결하지 못했습니다

During handling of the above exception, another exception occurred:

Traceback (most recent call last):
  File "C:\Users\kai\PycharmProjects\pythonProject\noname\noname\spiders\noname_spider.py", line 127, in company_scrapy
    menu1_button = self.driver.find_element_by_xpath(
  File "c:\users\kai\pycharmprojects\pythonproject\venv\lib\site-packages\selenium\webdriver\remote\webdriver.py", line 394, in find_element_by_xpath
    return self.find_element(by=By.XPATH, value=xpath)
  File "c:\users\kai\pycharmprojects\pythonproject\venv\lib\site-packages\selenium\webdriver\remote\webdriver.py", line 976, in find_element
    return self.execute(Command.FIND_ELEMENT, {
  File "c:\users\kai\pycharmprojects\pythonproject\venv\lib\site-packages\selenium\webdriver\remote\webdriver.py", line 319, in execute
    response = self.command_executor.execute(driver_command, params)
  File "c:\users\kai\pycharmprojects\pythonproject\venv\lib\site-packages\selenium\webdriver\remote\remote_connection.py", line 374, in execute
    return self._request(command_info[0], url, body=data)
  File "c:\users\kai\pycharmprojects\pythonproject\venv\lib\site-packages\selenium\webdriver\remote\remote_connection.py", line 397, in _request
    resp = self._conn.request(method, url, body=body, headers=headers)
  File "c:\users\kai\pycharmprojects\pythonproject\venv\lib\site-packages\urllib3\request.py", line 78, in request
    return self.request_encode_body(
  File "c:\users\kai\pycharmprojects\pythonproject\venv\lib\site-packages\urllib3\request.py", line 170, in request_encode_body
    return self.urlopen(method, url, **extra_kw)
  File "c:\users\kai\pycharmprojects\pythonproject\venv\lib\site-packages\urllib3\poolmanager.py", line 375, in urlopen
    response = conn.urlopen(method, u.request_uri, **kw)
  File "c:\users\kai\pycharmprojects\pythonproject\venv\lib\site-packages\urllib3\connectionpool.py", line 783, in urlopen
    return self.urlopen(
  File "c:\users\kai\pycharmprojects\pythonproject\venv\lib\site-packages\urllib3\connectionpool.py", line 783, in urlopen
    return self.urlopen(
  File "c:\users\kai\pycharmprojects\pythonproject\venv\lib\site-packages\urllib3\connectionpool.py", line 783, in urlopen
    return self.urlopen(
  File "c:\users\kai\pycharmprojects\pythonproject\venv\lib\site-packages\urllib3\connectionpool.py", line 755, in urlopen
    retries = retries.increment(
  File "c:\users\kai\pycharmprojects\pythonproject\venv\lib\site-packages\urllib3\util\retry.py", line 574, in increment
    raise MaxRetryError(_pool, url, error or ResponseError(cause))
urllib3.exceptions.MaxRetryError: HTTPConnectionPool(host='127.0.0.1', port=49997): Max retries exceeded with url: /session/359abe9da78dd8b8f0cbdde75fdd0e09/element (Caused by NewConnectionError('<urllib3.connection.HTTPConnection object at 0x000001E5978EE1C0>: Failed to establish a new connection: [WinError 10061] 대상 컴퓨터에서 연결을 거부했으므로 연결하지 못했습니다'))
2021-07-15 20:12_094940_푸른기술
Traceback (most recent call last):
  File "C:\Users\kai\PycharmProjects\pythonProject\noname\noname\spiders\noname_spider.py", line 274, in company_scrapy
    button = self.driver.find_element_by_xpath(
  File "c:\users\kai\pycharmprojects\pythonproject\venv\lib\site-packages\selenium\webdriver\remote\webdriver.py", line 394, in find_element_by_xpath
    return self.find_element(by=By.XPATH, value=xpath)
  File "c:\users\kai\pycharmprojects\pythonproject\venv\lib\site-packages\selenium\webdriver\remote\webdriver.py", line 976, in find_element
    return self.execute(Command.FIND_ELEMENT, {
  File "c:\users\kai\pycharmprojects\pythonproject\venv\lib\site-packages\selenium\webdriver\remote\webdriver.py", line 321, in execute
    self.error_handler.check_response(response)
  File "c:\users\kai\pycharmprojects\pythonproject\venv\lib\site-packages\selenium\webdriver\remote\errorhandler.py", line 242, in check_response
    raise exception_class(message, screen, stacktrace)
selenium.common.exceptions.NoSuchElementException: Message: no such element: Unable to locate element: {"method":"xpath","selector":"//div[@id='root']/div/div[contains(@class,'deepsesarch-dropdown-items')]/div[1]"}
  (Session info: chrome=91.0.4472.124)

2021-07-15 20:27_096040_이트론
Traceback (most recent call last):
  File "C:\Users\kai\PycharmProjects\pythonProject\noname\noname\spiders\noname_spider.py", line 274, in company_scrapy
    button = self.driver.find_element_by_xpath(
  File "c:\users\kai\pycharmprojects\pythonproject\venv\lib\site-packages\selenium\webdriver\remote\webdriver.py", line 394, in find_element_by_xpath
    return self.find_element(by=By.XPATH, value=xpath)
  File "c:\users\kai\pycharmprojects\pythonproject\venv\lib\site-packages\selenium\webdriver\remote\webdriver.py", line 976, in find_element
    return self.execute(Command.FIND_ELEMENT, {
  File "c:\users\kai\pycharmprojects\pythonproject\venv\lib\site-packages\selenium\webdriver\remote\webdriver.py", line 321, in execute
    self.error_handler.check_response(response)
  File "c:\users\kai\pycharmprojects\pythonproject\venv\lib\site-packages\selenium\webdriver\remote\errorhandler.py", line 242, in check_response
    raise exception_class(message, screen, stacktrace)
selenium.common.exceptions.NoSuchElementException: Message: no such element: Unable to locate element: {"method":"xpath","selector":"//div[@id='root']/div/div[contains(@class,'deepsesarch-dropdown-items')]/div[1]"}
  (Session info: chrome=91.0.4472.124)

2021-07-15 20:31_096300_베트남개발1
Traceback (most recent call last):
  File "C:\Users\kai\PycharmProjects\pythonProject\noname\noname\spiders\noname_spider.py", line 283, in company_scrapy
    button = self.driver.find_element_by_xpath(
  File "c:\users\kai\pycharmprojects\pythonproject\venv\lib\site-packages\selenium\webdriver\remote\webdriver.py", line 394, in find_element_by_xpath
    return self.find_element(by=By.XPATH, value=xpath)
  File "c:\users\kai\pycharmprojects\pythonproject\venv\lib\site-packages\selenium\webdriver\remote\webdriver.py", line 976, in find_element
    return self.execute(Command.FIND_ELEMENT, {
  File "c:\users\kai\pycharmprojects\pythonproject\venv\lib\site-packages\selenium\webdriver\remote\webdriver.py", line 321, in execute
    self.error_handler.check_response(response)
  File "c:\users\kai\pycharmprojects\pythonproject\venv\lib\site-packages\selenium\webdriver\remote\errorhandler.py", line 242, in check_response
    raise exception_class(message, screen, stacktrace)
selenium.common.exceptions.NoSuchElementException: Message: no such element: Unable to locate element: {"method":"xpath","selector":"//div[@id='income-statement']//div[contains(@class,'table-container')]//span[@class='table-export-button']"}
  (Session info: chrome=91.0.4472.124)

2021-07-15 20:33_096300_베트남개발1
Traceback (most recent call last):
  File "C:\Users\kai\PycharmProjects\pythonProject\noname\noname\spiders\noname_spider.py", line 283, in company_scrapy
    button = self.driver.find_element_by_xpath(
  File "c:\users\kai\pycharmprojects\pythonproject\venv\lib\site-packages\selenium\webdriver\remote\webdriver.py", line 394, in find_element_by_xpath
    return self.find_element(by=By.XPATH, value=xpath)
  File "c:\users\kai\pycharmprojects\pythonproject\venv\lib\site-packages\selenium\webdriver\remote\webdriver.py", line 976, in find_element
    return self.execute(Command.FIND_ELEMENT, {
  File "c:\users\kai\pycharmprojects\pythonproject\venv\lib\site-packages\selenium\webdriver\remote\webdriver.py", line 321, in execute
    self.error_handler.check_response(response)
  File "c:\users\kai\pycharmprojects\pythonproject\venv\lib\site-packages\selenium\webdriver\remote\errorhandler.py", line 242, in check_response
    raise exception_class(message, screen, stacktrace)
selenium.common.exceptions.NoSuchElementException: Message: no such element: Unable to locate element: {"method":"xpath","selector":"//div[@id='income-statement']//div[contains(@class,'table-container')]//span[@class='table-export-button']"}
  (Session info: chrome=91.0.4472.124)

2021-07-15 20:34_096300_베트남개발1
Traceback (most recent call last):
  File "C:\Users\kai\PycharmProjects\pythonProject\noname\noname\spiders\noname_spider.py", line 283, in company_scrapy
    button = self.driver.find_element_by_xpath(
  File "c:\users\kai\pycharmprojects\pythonproject\venv\lib\site-packages\selenium\webdriver\remote\webdriver.py", line 394, in find_element_by_xpath
    return self.find_element(by=By.XPATH, value=xpath)
  File "c:\users\kai\pycharmprojects\pythonproject\venv\lib\site-packages\selenium\webdriver\remote\webdriver.py", line 976, in find_element
    return self.execute(Command.FIND_ELEMENT, {
  File "c:\users\kai\pycharmprojects\pythonproject\venv\lib\site-packages\selenium\webdriver\remote\webdriver.py", line 321, in execute
    self.error_handler.check_response(response)
  File "c:\users\kai\pycharmprojects\pythonproject\venv\lib\site-packages\selenium\webdriver\remote\errorhandler.py", line 242, in check_response
    raise exception_class(message, screen, stacktrace)
selenium.common.exceptions.NoSuchElementException: Message: no such element: Unable to locate element: {"method":"xpath","selector":"//div[@id='income-statement']//div[contains(@class,'table-container')]//span[@class='table-export-button']"}
  (Session info: chrome=91.0.4472.124)

2021-07-15 21:02_099520_ITX-AI
Traceback (most recent call last):
  File "C:\Users\kai\PycharmProjects\pythonProject\noname\noname\spiders\noname_spider.py", line 274, in company_scrapy
    button = self.driver.find_element_by_xpath(
  File "c:\users\kai\pycharmprojects\pythonproject\venv\lib\site-packages\selenium\webdriver\remote\webdriver.py", line 394, in find_element_by_xpath
    return self.find_element(by=By.XPATH, value=xpath)
  File "c:\users\kai\pycharmprojects\pythonproject\venv\lib\site-packages\selenium\webdriver\remote\webdriver.py", line 976, in find_element
    return self.execute(Command.FIND_ELEMENT, {
  File "c:\users\kai\pycharmprojects\pythonproject\venv\lib\site-packages\selenium\webdriver\remote\webdriver.py", line 321, in execute
    self.error_handler.check_response(response)
  File "c:\users\kai\pycharmprojects\pythonproject\venv\lib\site-packages\selenium\webdriver\remote\errorhandler.py", line 242, in check_response
    raise exception_class(message, screen, stacktrace)
selenium.common.exceptions.NoSuchElementException: Message: no such element: Unable to locate element: {"method":"xpath","selector":"//div[@id='root']/div/div[contains(@class,'deepsesarch-dropdown-items')]/div[1]"}
  (Session info: chrome=91.0.4472.124)

2021-07-15 21:08_100090_삼강엠앤티
Traceback (most recent call last):
  File "C:\Users\kai\PycharmProjects\pythonProject\noname\noname\spiders\noname_spider.py", line 274, in company_scrapy
    button = self.driver.find_element_by_xpath(
  File "c:\users\kai\pycharmprojects\pythonproject\venv\lib\site-packages\selenium\webdriver\remote\webdriver.py", line 394, in find_element_by_xpath
    return self.find_element(by=By.XPATH, value=xpath)
  File "c:\users\kai\pycharmprojects\pythonproject\venv\lib\site-packages\selenium\webdriver\remote\webdriver.py", line 976, in find_element
    return self.execute(Command.FIND_ELEMENT, {
  File "c:\users\kai\pycharmprojects\pythonproject\venv\lib\site-packages\selenium\webdriver\remote\webdriver.py", line 321, in execute
    self.error_handler.check_response(response)
  File "c:\users\kai\pycharmprojects\pythonproject\venv\lib\site-packages\selenium\webdriver\remote\errorhandler.py", line 242, in check_response
    raise exception_class(message, screen, stacktrace)
selenium.common.exceptions.NoSuchElementException: Message: no such element: Unable to locate element: {"method":"xpath","selector":"//div[@id='root']/div/div[contains(@class,'deepsesarch-dropdown-items')]/div[1]"}
  (Session info: chrome=91.0.4472.124)

2021-07-15 21:21_101170_우림기계
Traceback (most recent call last):
  File "C:\Users\kai\PycharmProjects\pythonProject\noname\noname\spiders\noname_spider.py", line 274, in company_scrapy
    button = self.driver.find_element_by_xpath(
  File "c:\users\kai\pycharmprojects\pythonproject\venv\lib\site-packages\selenium\webdriver\remote\webdriver.py", line 394, in find_element_by_xpath
    return self.find_element(by=By.XPATH, value=xpath)
  File "c:\users\kai\pycharmprojects\pythonproject\venv\lib\site-packages\selenium\webdriver\remote\webdriver.py", line 976, in find_element
    return self.execute(Command.FIND_ELEMENT, {
  File "c:\users\kai\pycharmprojects\pythonproject\venv\lib\site-packages\selenium\webdriver\remote\webdriver.py", line 321, in execute
    self.error_handler.check_response(response)
  File "c:\users\kai\pycharmprojects\pythonproject\venv\lib\site-packages\selenium\webdriver\remote\errorhandler.py", line 242, in check_response
    raise exception_class(message, screen, stacktrace)
selenium.common.exceptions.NoSuchElementException: Message: no such element: Unable to locate element: {"method":"xpath","selector":"//div[@id='root']/div/div[contains(@class,'deepsesarch-dropdown-items')]/div[1]"}
  (Session info: chrome=91.0.4472.124)

2021-07-15 21:27_101360_이엔드디
Traceback (most recent call last):
  File "C:\Users\kai\PycharmProjects\pythonProject\noname\noname\spiders\noname_spider.py", line 274, in company_scrapy
    button = self.driver.find_element_by_xpath(
  File "c:\users\kai\pycharmprojects\pythonproject\venv\lib\site-packages\selenium\webdriver\remote\webdriver.py", line 394, in find_element_by_xpath
    return self.find_element(by=By.XPATH, value=xpath)
  File "c:\users\kai\pycharmprojects\pythonproject\venv\lib\site-packages\selenium\webdriver\remote\webdriver.py", line 976, in find_element
    return self.execute(Command.FIND_ELEMENT, {
  File "c:\users\kai\pycharmprojects\pythonproject\venv\lib\site-packages\selenium\webdriver\remote\webdriver.py", line 321, in execute
    self.error_handler.check_response(response)
  File "c:\users\kai\pycharmprojects\pythonproject\venv\lib\site-packages\selenium\webdriver\remote\errorhandler.py", line 242, in check_response
    raise exception_class(message, screen, stacktrace)
selenium.common.exceptions.NoSuchElementException: Message: no such element: Unable to locate element: {"method":"xpath","selector":"//div[@id='root']/div/div[contains(@class,'deepsesarch-dropdown-items')]/div[1]"}
  (Session info: chrome=91.0.4472.124)

2021-07-15 21:33_101670_코리아에스이
Traceback (most recent call last):
  File "C:\Users\kai\PycharmProjects\pythonProject\noname\noname\spiders\noname_spider.py", line 274, in company_scrapy
    button = self.driver.find_element_by_xpath(
  File "c:\users\kai\pycharmprojects\pythonproject\venv\lib\site-packages\selenium\webdriver\remote\webdriver.py", line 394, in find_element_by_xpath
    return self.find_element(by=By.XPATH, value=xpath)
  File "c:\users\kai\pycharmprojects\pythonproject\venv\lib\site-packages\selenium\webdriver\remote\webdriver.py", line 976, in find_element
    return self.execute(Command.FIND_ELEMENT, {
  File "c:\users\kai\pycharmprojects\pythonproject\venv\lib\site-packages\selenium\webdriver\remote\webdriver.py", line 321, in execute
    self.error_handler.check_response(response)
  File "c:\users\kai\pycharmprojects\pythonproject\venv\lib\site-packages\selenium\webdriver\remote\errorhandler.py", line 242, in check_response
    raise exception_class(message, screen, stacktrace)
selenium.common.exceptions.NoSuchElementException: Message: no such element: Unable to locate element: {"method":"xpath","selector":"//div[@id='root']/div/div[contains(@class,'deepsesarch-dropdown-items')]/div[1]"}
  (Session info: chrome=91.0.4472.124)

2021-07-15 21:52_104480_티케이케미칼
Traceback (most recent call last):
  File "C:\Users\kai\PycharmProjects\pythonProject\noname\noname\spiders\noname_spider.py", line 274, in company_scrapy
    button = self.driver.find_element_by_xpath(
  File "c:\users\kai\pycharmprojects\pythonproject\venv\lib\site-packages\selenium\webdriver\remote\webdriver.py", line 394, in find_element_by_xpath
    return self.find_element(by=By.XPATH, value=xpath)
  File "c:\users\kai\pycharmprojects\pythonproject\venv\lib\site-packages\selenium\webdriver\remote\webdriver.py", line 976, in find_element
    return self.execute(Command.FIND_ELEMENT, {
  File "c:\users\kai\pycharmprojects\pythonproject\venv\lib\site-packages\selenium\webdriver\remote\webdriver.py", line 321, in execute
    self.error_handler.check_response(response)
  File "c:\users\kai\pycharmprojects\pythonproject\venv\lib\site-packages\selenium\webdriver\remote\errorhandler.py", line 242, in check_response
    raise exception_class(message, screen, stacktrace)
selenium.common.exceptions.NoSuchElementException: Message: no such element: Unable to locate element: {"method":"xpath","selector":"//div[@id='root']/div/div[contains(@class,'deepsesarch-dropdown-items')]/div[1]"}
  (Session info: chrome=91.0.4472.124)

2021-07-15 21:56_104620_노랑풍선
Traceback (most recent call last):
  File "C:\Users\kai\PycharmProjects\pythonProject\noname\noname\spiders\noname_spider.py", line 274, in company_scrapy
    button = self.driver.find_element_by_xpath(
  File "c:\users\kai\pycharmprojects\pythonproject\venv\lib\site-packages\selenium\webdriver\remote\webdriver.py", line 394, in find_element_by_xpath
    return self.find_element(by=By.XPATH, value=xpath)
  File "c:\users\kai\pycharmprojects\pythonproject\venv\lib\site-packages\selenium\webdriver\remote\webdriver.py", line 976, in find_element
    return self.execute(Command.FIND_ELEMENT, {
  File "c:\users\kai\pycharmprojects\pythonproject\venv\lib\site-packages\selenium\webdriver\remote\webdriver.py", line 321, in execute
    self.error_handler.check_response(response)
  File "c:\users\kai\pycharmprojects\pythonproject\venv\lib\site-packages\selenium\webdriver\remote\errorhandler.py", line 242, in check_response
    raise exception_class(message, screen, stacktrace)
selenium.common.exceptions.NoSuchElementException: Message: no such element: Unable to locate element: {"method":"xpath","selector":"//div[@id='root']/div/div[contains(@class,'deepsesarch-dropdown-items')]/div[1]"}
  (Session info: chrome=91.0.4472.124)

2021-07-15 22:15_108490_로보티즈
Traceback (most recent call last):
  File "C:\Users\kai\PycharmProjects\pythonProject\noname\noname\spiders\noname_spider.py", line 274, in company_scrapy
    button = self.driver.find_element_by_xpath(
  File "c:\users\kai\pycharmprojects\pythonproject\venv\lib\site-packages\selenium\webdriver\remote\webdriver.py", line 394, in find_element_by_xpath
    return self.find_element(by=By.XPATH, value=xpath)
  File "c:\users\kai\pycharmprojects\pythonproject\venv\lib\site-packages\selenium\webdriver\remote\webdriver.py", line 976, in find_element
    return self.execute(Command.FIND_ELEMENT, {
  File "c:\users\kai\pycharmprojects\pythonproject\venv\lib\site-packages\selenium\webdriver\remote\webdriver.py", line 321, in execute
    self.error_handler.check_response(response)
  File "c:\users\kai\pycharmprojects\pythonproject\venv\lib\site-packages\selenium\webdriver\remote\errorhandler.py", line 242, in check_response
    raise exception_class(message, screen, stacktrace)
selenium.common.exceptions.NoSuchElementException: Message: no such element: Unable to locate element: {"method":"xpath","selector":"//div[@id='root']/div/div[contains(@class,'deepsesarch-dropdown-items')]/div[1]"}
  (Session info: chrome=91.0.4472.124)

2021-07-15 22:31_110790_크리스에프앤씨
Traceback (most recent call last):
  File "C:\Users\kai\PycharmProjects\pythonProject\noname\noname\spiders\noname_spider.py", line 274, in company_scrapy
    button = self.driver.find_element_by_xpath(
  File "c:\users\kai\pycharmprojects\pythonproject\venv\lib\site-packages\selenium\webdriver\remote\webdriver.py", line 394, in find_element_by_xpath
    return self.find_element(by=By.XPATH, value=xpath)
  File "c:\users\kai\pycharmprojects\pythonproject\venv\lib\site-packages\selenium\webdriver\remote\webdriver.py", line 976, in find_element
    return self.execute(Command.FIND_ELEMENT, {
  File "c:\users\kai\pycharmprojects\pythonproject\venv\lib\site-packages\selenium\webdriver\remote\webdriver.py", line 321, in execute
    self.error_handler.check_response(response)
  File "c:\users\kai\pycharmprojects\pythonproject\venv\lib\site-packages\selenium\webdriver\remote\errorhandler.py", line 242, in check_response
    raise exception_class(message, screen, stacktrace)
selenium.common.exceptions.NoSuchElementException: Message: no such element: Unable to locate element: {"method":"xpath","selector":"//div[@id='root']/div/div[contains(@class,'deepsesarch-dropdown-items')]/div[1]"}
  (Session info: chrome=91.0.4472.124)

2021-07-15 22:35_111710_남화산업
Traceback (most recent call last):
  File "C:\Users\kai\PycharmProjects\pythonProject\noname\noname\spiders\noname_spider.py", line 274, in company_scrapy
    button = self.driver.find_element_by_xpath(
  File "c:\users\kai\pycharmprojects\pythonproject\venv\lib\site-packages\selenium\webdriver\remote\webdriver.py", line 394, in find_element_by_xpath
    return self.find_element(by=By.XPATH, value=xpath)
  File "c:\users\kai\pycharmprojects\pythonproject\venv\lib\site-packages\selenium\webdriver\remote\webdriver.py", line 976, in find_element
    return self.execute(Command.FIND_ELEMENT, {
  File "c:\users\kai\pycharmprojects\pythonproject\venv\lib\site-packages\selenium\webdriver\remote\webdriver.py", line 321, in execute
    self.error_handler.check_response(response)
  File "c:\users\kai\pycharmprojects\pythonproject\venv\lib\site-packages\selenium\webdriver\remote\errorhandler.py", line 242, in check_response
    raise exception_class(message, screen, stacktrace)
selenium.common.exceptions.NoSuchElementException: Message: no such element: Unable to locate element: {"method":"xpath","selector":"//div[@id='root']/div/div[contains(@class,'deepsesarch-dropdown-items')]/div[1]"}
  (Session info: chrome=91.0.4472.124)

2021-07-15 22:42_112190_KC산업
Traceback (most recent call last):
  File "C:\Users\kai\PycharmProjects\pythonProject\noname\noname\spiders\noname_spider.py", line 274, in company_scrapy
    button = self.driver.find_element_by_xpath(
  File "c:\users\kai\pycharmprojects\pythonproject\venv\lib\site-packages\selenium\webdriver\remote\webdriver.py", line 394, in find_element_by_xpath
    return self.find_element(by=By.XPATH, value=xpath)
  File "c:\users\kai\pycharmprojects\pythonproject\venv\lib\site-packages\selenium\webdriver\remote\webdriver.py", line 976, in find_element
    return self.execute(Command.FIND_ELEMENT, {
  File "c:\users\kai\pycharmprojects\pythonproject\venv\lib\site-packages\selenium\webdriver\remote\webdriver.py", line 321, in execute
    self.error_handler.check_response(response)
  File "c:\users\kai\pycharmprojects\pythonproject\venv\lib\site-packages\selenium\webdriver\remote\errorhandler.py", line 242, in check_response
    raise exception_class(message, screen, stacktrace)
selenium.common.exceptions.NoSuchElementException: Message: no such element: Unable to locate element: {"method":"xpath","selector":"//div[@id='root']/div/div[contains(@class,'deepsesarch-dropdown-items')]/div[1]"}
  (Session info: chrome=91.0.4472.124)

2021-07-15 22:47_114190_강원
Traceback (most recent call last):
  File "C:\Users\kai\PycharmProjects\pythonProject\noname\noname\spiders\noname_spider.py", line 250, in company_scrapy
    button = self.driver.find_element_by_xpath(
  File "c:\users\kai\pycharmprojects\pythonproject\venv\lib\site-packages\selenium\webdriver\remote\webdriver.py", line 394, in find_element_by_xpath
    return self.find_element(by=By.XPATH, value=xpath)
  File "c:\users\kai\pycharmprojects\pythonproject\venv\lib\site-packages\selenium\webdriver\remote\webdriver.py", line 976, in find_element
    return self.execute(Command.FIND_ELEMENT, {
  File "c:\users\kai\pycharmprojects\pythonproject\venv\lib\site-packages\selenium\webdriver\remote\webdriver.py", line 321, in execute
    self.error_handler.check_response(response)
  File "c:\users\kai\pycharmprojects\pythonproject\venv\lib\site-packages\selenium\webdriver\remote\errorhandler.py", line 242, in check_response
    raise exception_class(message, screen, stacktrace)
selenium.common.exceptions.NoSuchElementException: Message: no such element: Unable to locate element: {"method":"xpath","selector":"//div[@id='income-statement']//div[contains(@class,'header-text')]//div[contains(@class,'options')]/div[1]/div"}
  (Session info: chrome=91.0.4472.124)

2021-07-15 22:54_114810_아이원스
Traceback (most recent call last):
  File "C:\Users\kai\PycharmProjects\pythonProject\noname\noname\spiders\noname_spider.py", line 274, in company_scrapy
    button = self.driver.find_element_by_xpath(
  File "c:\users\kai\pycharmprojects\pythonproject\venv\lib\site-packages\selenium\webdriver\remote\webdriver.py", line 394, in find_element_by_xpath
    return self.find_element(by=By.XPATH, value=xpath)
  File "c:\users\kai\pycharmprojects\pythonproject\venv\lib\site-packages\selenium\webdriver\remote\webdriver.py", line 976, in find_element
    return self.execute(Command.FIND_ELEMENT, {
  File "c:\users\kai\pycharmprojects\pythonproject\venv\lib\site-packages\selenium\webdriver\remote\webdriver.py", line 321, in execute
    self.error_handler.check_response(response)
  File "c:\users\kai\pycharmprojects\pythonproject\venv\lib\site-packages\selenium\webdriver\remote\errorhandler.py", line 242, in check_response
    raise exception_class(message, screen, stacktrace)
selenium.common.exceptions.NoSuchElementException: Message: no such element: Unable to locate element: {"method":"xpath","selector":"//div[@id='root']/div/div[contains(@class,'deepsesarch-dropdown-items')]/div[1]"}
  (Session info: chrome=91.0.4472.124)

2021-07-15 22:56_114920_대주이엔티
Traceback (most recent call last):
  File "C:\Users\kai\PycharmProjects\pythonProject\noname\noname\spiders\noname_spider.py", line 274, in company_scrapy
    button = self.driver.find_element_by_xpath(
  File "c:\users\kai\pycharmprojects\pythonproject\venv\lib\site-packages\selenium\webdriver\remote\webdriver.py", line 394, in find_element_by_xpath
    return self.find_element(by=By.XPATH, value=xpath)
  File "c:\users\kai\pycharmprojects\pythonproject\venv\lib\site-packages\selenium\webdriver\remote\webdriver.py", line 976, in find_element
    return self.execute(Command.FIND_ELEMENT, {
  File "c:\users\kai\pycharmprojects\pythonproject\venv\lib\site-packages\selenium\webdriver\remote\webdriver.py", line 321, in execute
    self.error_handler.check_response(response)
  File "c:\users\kai\pycharmprojects\pythonproject\venv\lib\site-packages\selenium\webdriver\remote\errorhandler.py", line 242, in check_response
    raise exception_class(message, screen, stacktrace)
selenium.common.exceptions.NoSuchElementException: Message: no such element: Unable to locate element: {"method":"xpath","selector":"//div[@id='root']/div/div[contains(@class,'deepsesarch-dropdown-items')]/div[1]"}
  (Session info: chrome=91.0.4472.124)

2021-07-15 23:14_116100_태양기계
Traceback (most recent call last):
  File "C:\Users\kai\PycharmProjects\pythonProject\noname\noname\spiders\noname_spider.py", line 274, in company_scrapy
    button = self.driver.find_element_by_xpath(
  File "c:\users\kai\pycharmprojects\pythonproject\venv\lib\site-packages\selenium\webdriver\remote\webdriver.py", line 394, in find_element_by_xpath
    return self.find_element(by=By.XPATH, value=xpath)
  File "c:\users\kai\pycharmprojects\pythonproject\venv\lib\site-packages\selenium\webdriver\remote\webdriver.py", line 976, in find_element
    return self.execute(Command.FIND_ELEMENT, {
  File "c:\users\kai\pycharmprojects\pythonproject\venv\lib\site-packages\selenium\webdriver\remote\webdriver.py", line 321, in execute
    self.error_handler.check_response(response)
  File "c:\users\kai\pycharmprojects\pythonproject\venv\lib\site-packages\selenium\webdriver\remote\errorhandler.py", line 242, in check_response
    raise exception_class(message, screen, stacktrace)
selenium.common.exceptions.NoSuchElementException: Message: no such element: Unable to locate element: {"method":"xpath","selector":"//div[@id='root']/div/div[contains(@class,'deepsesarch-dropdown-items')]/div[1]"}
  (Session info: chrome=91.0.4472.124)

2021-07-15 23:17_117730_티로보틱스
Traceback (most recent call last):
  File "C:\Users\kai\PycharmProjects\pythonProject\noname\noname\spiders\noname_spider.py", line 274, in company_scrapy
    button = self.driver.find_element_by_xpath(
  File "c:\users\kai\pycharmprojects\pythonproject\venv\lib\site-packages\selenium\webdriver\remote\webdriver.py", line 394, in find_element_by_xpath
    return self.find_element(by=By.XPATH, value=xpath)
  File "c:\users\kai\pycharmprojects\pythonproject\venv\lib\site-packages\selenium\webdriver\remote\webdriver.py", line 976, in find_element
    return self.execute(Command.FIND_ELEMENT, {
  File "c:\users\kai\pycharmprojects\pythonproject\venv\lib\site-packages\selenium\webdriver\remote\webdriver.py", line 321, in execute
    self.error_handler.check_response(response)
  File "c:\users\kai\pycharmprojects\pythonproject\venv\lib\site-packages\selenium\webdriver\remote\errorhandler.py", line 242, in check_response
    raise exception_class(message, screen, stacktrace)
selenium.common.exceptions.NoSuchElementException: Message: no such element: Unable to locate element: {"method":"xpath","selector":"//div[@id='root']/div/div[contains(@class,'deepsesarch-dropdown-items')]/div[1]"}
  (Session info: chrome=91.0.4472.124)

2021-07-15 23:20_118990_모트렉스
Traceback (most recent call last):
  File "C:\Users\kai\PycharmProjects\pythonProject\noname\noname\spiders\noname_spider.py", line 274, in company_scrapy
    button = self.driver.find_element_by_xpath(
  File "c:\users\kai\pycharmprojects\pythonproject\venv\lib\site-packages\selenium\webdriver\remote\webdriver.py", line 394, in find_element_by_xpath
    return self.find_element(by=By.XPATH, value=xpath)
  File "c:\users\kai\pycharmprojects\pythonproject\venv\lib\site-packages\selenium\webdriver\remote\webdriver.py", line 976, in find_element
    return self.execute(Command.FIND_ELEMENT, {
  File "c:\users\kai\pycharmprojects\pythonproject\venv\lib\site-packages\selenium\webdriver\remote\webdriver.py", line 321, in execute
    self.error_handler.check_response(response)
  File "c:\users\kai\pycharmprojects\pythonproject\venv\lib\site-packages\selenium\webdriver\remote\errorhandler.py", line 242, in check_response
    raise exception_class(message, screen, stacktrace)
selenium.common.exceptions.NoSuchElementException: Message: no such element: Unable to locate element: {"method":"xpath","selector":"//div[@id='root']/div/div[contains(@class,'deepsesarch-dropdown-items')]/div[1]"}
  (Session info: chrome=91.0.4472.124)

2021-07-15 23:22_118990_모트렉스
Traceback (most recent call last):
  File "C:\Users\kai\PycharmProjects\pythonProject\noname\noname\spiders\noname_spider.py", line 274, in company_scrapy
    button = self.driver.find_element_by_xpath(
  File "c:\users\kai\pycharmprojects\pythonproject\venv\lib\site-packages\selenium\webdriver\remote\webdriver.py", line 394, in find_element_by_xpath
    return self.find_element(by=By.XPATH, value=xpath)
  File "c:\users\kai\pycharmprojects\pythonproject\venv\lib\site-packages\selenium\webdriver\remote\webdriver.py", line 976, in find_element
    return self.execute(Command.FIND_ELEMENT, {
  File "c:\users\kai\pycharmprojects\pythonproject\venv\lib\site-packages\selenium\webdriver\remote\webdriver.py", line 321, in execute
    self.error_handler.check_response(response)
  File "c:\users\kai\pycharmprojects\pythonproject\venv\lib\site-packages\selenium\webdriver\remote\errorhandler.py", line 242, in check_response
    raise exception_class(message, screen, stacktrace)
selenium.common.exceptions.NoSuchElementException: Message: no such element: Unable to locate element: {"method":"xpath","selector":"//div[@id='root']/div/div[contains(@class,'deepsesarch-dropdown-items')]/div[1]"}
  (Session info: chrome=91.0.4472.124)

2021-07-15 23:33_121060_유니포인트
Traceback (most recent call last):
  File "C:\Users\kai\PycharmProjects\pythonProject\noname\noname\spiders\noname_spider.py", line 274, in company_scrapy
    button = self.driver.find_element_by_xpath(
  File "c:\users\kai\pycharmprojects\pythonproject\venv\lib\site-packages\selenium\webdriver\remote\webdriver.py", line 394, in find_element_by_xpath
    return self.find_element(by=By.XPATH, value=xpath)
  File "c:\users\kai\pycharmprojects\pythonproject\venv\lib\site-packages\selenium\webdriver\remote\webdriver.py", line 976, in find_element
    return self.execute(Command.FIND_ELEMENT, {
  File "c:\users\kai\pycharmprojects\pythonproject\venv\lib\site-packages\selenium\webdriver\remote\webdriver.py", line 321, in execute
    self.error_handler.check_response(response)
  File "c:\users\kai\pycharmprojects\pythonproject\venv\lib\site-packages\selenium\webdriver\remote\errorhandler.py", line 242, in check_response
    raise exception_class(message, screen, stacktrace)
selenium.common.exceptions.NoSuchElementException: Message: no such element: Unable to locate element: {"method":"xpath","selector":"//div[@id='root']/div/div[contains(@class,'deepsesarch-dropdown-items')]/div[1]"}
  (Session info: chrome=91.0.4472.124)

2021-07-15 23:43_122310_제노레이
Traceback (most recent call last):
  File "C:\Users\kai\PycharmProjects\pythonProject\noname\noname\spiders\noname_spider.py", line 274, in company_scrapy
    button = self.driver.find_element_by_xpath(
  File "c:\users\kai\pycharmprojects\pythonproject\venv\lib\site-packages\selenium\webdriver\remote\webdriver.py", line 394, in find_element_by_xpath
    return self.find_element(by=By.XPATH, value=xpath)
  File "c:\users\kai\pycharmprojects\pythonproject\venv\lib\site-packages\selenium\webdriver\remote\webdriver.py", line 976, in find_element
    return self.execute(Command.FIND_ELEMENT, {
  File "c:\users\kai\pycharmprojects\pythonproject\venv\lib\site-packages\selenium\webdriver\remote\webdriver.py", line 321, in execute
    self.error_handler.check_response(response)
  File "c:\users\kai\pycharmprojects\pythonproject\venv\lib\site-packages\selenium\webdriver\remote\errorhandler.py", line 242, in check_response
    raise exception_class(message, screen, stacktrace)
selenium.common.exceptions.NoSuchElementException: Message: no such element: Unable to locate element: {"method":"xpath","selector":"//div[@id='root']/div/div[contains(@class,'deepsesarch-dropdown-items')]/div[1]"}
  (Session info: chrome=91.0.4472.124)

2021-07-15 23:47_122640_예스티
Traceback (most recent call last):
  File "C:\Users\kai\PycharmProjects\pythonProject\noname\noname\spiders\noname_spider.py", line 278, in company_scrapy
    data_type = button.find_element_by_xpath("./div").text
  File "c:\users\kai\pycharmprojects\pythonproject\venv\lib\site-packages\selenium\webdriver\remote\webelement.py", line 351, in find_element_by_xpath
    return self.find_element(by=By.XPATH, value=xpath)
  File "c:\users\kai\pycharmprojects\pythonproject\venv\lib\site-packages\selenium\webdriver\remote\webelement.py", line 658, in find_element
    return self._execute(Command.FIND_CHILD_ELEMENT,
  File "c:\users\kai\pycharmprojects\pythonproject\venv\lib\site-packages\selenium\webdriver\remote\webelement.py", line 633, in _execute
    return self._parent.execute(command, params)
  File "c:\users\kai\pycharmprojects\pythonproject\venv\lib\site-packages\selenium\webdriver\remote\webdriver.py", line 321, in execute
    self.error_handler.check_response(response)
  File "c:\users\kai\pycharmprojects\pythonproject\venv\lib\site-packages\selenium\webdriver\remote\errorhandler.py", line 242, in check_response
    raise exception_class(message, screen, stacktrace)
selenium.common.exceptions.StaleElementReferenceException: Message: stale element reference: element is not attached to the page document
  (Session info: chrome=91.0.4472.124)

